Workbook

Sheet group_data_final
A1: division_name | B1: district_name | C1: depot_code | D1: length_to2 | E1: veh_total | F1: veh_truck | G1: avg_iri | H1: length_ac | I1: lanemin_ac | J1: lanemax_ac | K1: laneavg_ac | L1: pavewidthavg_ac | M1: shoulderwidthavg_ac | N1: length_cc | O1: lanemin_cc | P1: lanemax_cc | Q1: laneavg_cc | R1: pavewidthavg_cc | S1: shoulderwidthavg_cc | T1: bicyclelane_sqm | U1: rest_area_sqm | V1: sidewalk_sqm | W1: retainingwall_sqm | X1: roadmarking_sqm | Y1: road_medians_m | Z1: elevation_mean | AA1: elevation_var | AB1: slope_mean | AC1: slope_var | AD1: ค่าบำรุงตามระยะทางต่อ 2 ช่องจราจร | AE1: ค่าบำรุงทรัพย์สิน | AF1: จำนวนจุดกางเต็นท์ | AG1: ค่าบำรุงจุดกางเต็นท์ | AH1: จำนวนจุดพักรถ | AI1: ค่าบำรุงจุดพักรถ | AJ1: จำนวนภูมิสถาปัตย์ | AK1: ค่าบำรุงภูมิสถาปัตย์ | AL1: พื้นที่ฝนชุก | AM1: sum_งบแผน68 | AN1: bridge_m
A2: สำนักงานทางหลวงที่ 18 (สงขลา) | B2: ขท.สงขลาที่ 1 | C2: 311 | D2: {=_xlfn.LET(_xlpm.result,INDEX(ระยะทาง!C:C, MATCH(TRIM(C2), TRIM(ระยะทาง!$A:$A), 0)),IF(ISNUMBER(SEARCH("-", _xlpm.result)), 0, _xlpm.result))} -> 718.5 | E2: {=_xlfn.LET(_xlpm.result,INDEX(ระยะทาง!D:D, MATCH(TRIM($C2), TRIM(ระยะทาง!$A:$A), 0)),IF(ISNUMBER(SEARCH("-", _xlpm.result)), 0, _xlpm.result))} -> 1383993728 | F2: 174531184 | G2: 2.6982222 | H2: 249.258 | I2: 1 | J2: 8 | K2: 4.4444444 | L2: 3.714 | M2: 5 | N2: 27.281 | O2: 2 | P2: 10 | Q2: 5.1428571 | R2: 3.4928571 | S2: 5.0372 | T2: 0 | U2: 0 | V2: 31795.915 | W2: 14974 | X2: 46223.154 | Y2: 32681 | Z2: 18.305699 | AA2: 60.633393 | AB2: -0.035941715 | AC2: 14.665243 | AD2: =D2*'ราคาต้นทุน (Asset)'!$E$1 -> 43110000 | AE2: {=_xlfn.LET(_xlpm.result,INDEX(ASSET!U:U, MATCH(TRIM($C2), TRIM(ASSET!$A:$A), 0)),IF(ISNUMBER(SEARCH("-", _xlpm.result)), 0, _xlpm.result))} -> 4993000 | AF2: =group_data_final[[#This Row],[ค่าบำรุงจุดกางเต็นท์]]/300000 -> 0 | AG2: {=_xlfn.LET(_xlpm.result,INDEX(ราคาค่าบำรุง!D:D, MATCH(TRIM($C2), TRIM(ราคาค่าบำรุง!$A:$A), 0)),IF(ISNUMBER(SEARCH("-", _xlpm.result)), 0, _xlpm.result))} -> 0 | AH2: =group_data_final[[#This Row],[ค่าบำรุงจุดพักรถ]]/300000 -> 0 | AI2: {=_xlfn.LET(_xlpm.result,INDEX(ราคาค่าบำรุง!F:F, MATCH(TRIM($C2), TRIM(ราคาค่าบำรุง!$A:$A), 0)),IF(ISNUMBER(SEARCH("-", _xlpm.result)), 0, _xlpm.result))} -> 0 | AJ2: =group_data_final[[#This Row],[ค่าบำรุงภูมิสถาปัตย์]]/300000 -> 0 | AK2: {=_xlfn.LET(_xlpm.result,INDEX(ราคาค่าบำรุง!H:H, MATCH(TRIM($C2), TRIM(ราคาค่าบำรุง!$A:$A), 0)),IF(ISNUMBER(SEARCH("-", _xlpm.result)), 0, _xlpm.result))} -> 0 | AL2: =IF(OR(COUNTIF(B2,"*กระบี่*"),COUNTIF(B2,"*จันทบุรี*"),COUNTIF(B2,"*ชุมพร*"),COUNTIF(B2,"*เชียงราย*"),COUNTIF(B2,"*ตรัง*"),COUNTIF(B2,"*นครนายก*"),COUNTIF(B2,"*ปราจีนบุรี*"),COUNTIF(B2,"*พัทลุง*"),COUNTIF(B2,"*ภูเก็ต*"),COUNTIF(B2,"*ยะลา*"),COUNTIF(B2,"*สกลนคร*"),COUNTIF(B2,"*สตูล*"),COUNTIF(B2,"*หนองคาย*"),COUNTIF(B2,"*สุราษฎร์ธานี*"),COUNTIF(B2,"*ปัตตานี*")),2, IF(OR(COUNTIF(B2,"*ตราด*"),COUNTIF(B2,"*นครพนม*"),COUNTIF(B2,"*นครศรีธรรมราช*"),COUNTIF(B2,"*นราธิวาส*"),COUNTIF(B2,"*บึงกาฬ*"),COUNTIF(B2,"*พังงา*"),COUNTIF(B2,"*ระนอง*"),COUNTIF(B2,"*สงขลา*")),4,0)) -> 4 | AM2: =_xlfn.XLOOKUP(group_data_final[[#This Row],[depot_code]],C:C,แผน68!D:D) -> 20573476 | AN2: 17246.602
A3: สำนักงานทางหลวงที่ 18 (สงขลา) | B3: ขท.ยะลา | C3: 312 | D3: {=_xlfn.LET(_xlpm.result,INDEX(ระยะทาง!C:C, MATCH(TRIM(C3), TRIM(ระยะทาง!$A:$A), 0)),IF(ISNUMBER(SEARCH("-", _xlpm.result)), 0, _xlpm.result))} -> 557.192 | E3: {=_xlfn.LET(_xlpm.result,INDEX(ระยะทาง!D:D, MATCH(TRIM($C3), TRIM(ระยะทาง!$A:$A), 0)),IF(ISNUMBER(SEARCH("-", _xlpm.result)), 0, _xlpm.result))} -> 1880891403 | F3: 125911304 | G3: 2.6982222 | H3: 557.192 | I3: 1 | J3: 8 | K3: 4.4444444 | L3: 3.714 | M3: 5 | N3: 0 | O3: 2 | P3: 10 | Q3: 5.1428571 | R3: 3.4928571 | S3: 5.0372 | T3: 0 | U3: 0 | V3: 31795.915 | W3: 14974 | X3: 46223.154 | Y3: 32681 | Z3: 18.305699 | AA3: 60.633393 | AB3: -0.035941715 | AC3: 14.665243 | AD3: =D3*'ราคาต้นทุน (Asset)'!$E$1 -> 33431520 | AE3: {=_xlfn.LET(_xlpm.result,INDEX(ASSET!U:U, MATCH(TRIM($C3), TRIM(ASSET!$A:$A), 0)),IF(ISNUMBER(SEARCH("-", _xlpm.result)), 0, _xlpm.result))} -> 2795800 | AF3: =group_data_final[[#This Row],[ค่าบำรุงจุดกางเต็นท์]]/300000 -> 0 | AG3: {=_xlfn.LET(_xlpm.result,INDEX(ราคาค่าบำรุง!D:D, MATCH(TRIM($C3), TRIM(ราคาค่าบำรุง!$A:$A), 0)),IF(ISNUMBER(SEARCH("-", _xlpm.result)), 0, _xlpm.result))} -> 0 | AH3: =group_data_final[[#This Row],[ค่าบำรุงจุดพักรถ]]/300000 -> 1 | AI3: {=_xlfn.LET(_xlpm.result,INDEX(ราคาค่าบำรุง!F:F, MATCH(TRIM($C3), TRIM(ราคาค่าบำรุง!$A:$A), 0)),IF(ISNUMBER(SEARCH("-", _xlpm.result)), 0, _xlpm.result))} -> 300000 | AJ3: =group_data_final[[#This Row],[ค่าบำรุงภูมิสถาปัตย์]]/300000 -> 3 | AK3: {=_xlfn.LET(_xlpm.result,INDEX(ราคาค่าบำรุง!H:H, MATCH(TRIM($C3), TRIM(ราคาค่าบำรุง!$A:$A), 0)),IF(ISNUMBER(SEARCH("-", _xlpm.result)), 0, _xlpm.result))} -> 900000 | AL3: =IF(OR(COUNTIF(B3,"*กระบี่*"),COUNTIF(B3,"*จันทบุรี*"),COUNTIF(B3,"*ชุมพร*"),COUNTIF(B3,"*เชียงราย*"),COUNTIF(B3,"*ตรัง*"),COUNTIF(B3,"*นครนายก*"),COUNTIF(B3,"*ปราจีนบุรี*"),COUNTIF(B3,"*พัทลุง*"),COUNTIF(B3,"*ภูเก็ต*"),COUNTIF(B3,"*ยะลา*"),COUNTIF(B3,"*สกลนคร*"),COUNTIF(B3,"*สตูล*"),COUNTIF(B3,"*หนองคาย*"),COUNTIF(B3,"*สุราษฎร์ธานี*"),COUNTIF(B3,"*ปัตตานี*")),2, IF(OR(COUNTIF(B3,"*ตราด*"),COUNTIF(B3,"*นครพนม*"),COUNTIF(B3,"*นครศรีธรรมราช*"),COUNTIF(B3,"*นราธิวาส*"),COUNTIF(B3,"*บึงกาฬ*"),COUNTIF(B3,"*พังงา*"),COUNTIF(B3,"*ระนอง*"),COUNTIF(B3,"*สงขลา*")),4,0)) -> 2 | AM3: =_xlfn.XLOOKUP(group_data_final[[#This Row],[depot_code]],C:C,แผน68!D:D) -> 24198050 | AN3: 7504
A4: สำนักงานทางหลวงที่ 18 (สงขลา) | B4: ขท.ปัตตานี | C4: 313 | D4: {=_xlfn.LET(_xlpm.result,INDEX(ระยะทาง!C:C, MATCH(TRIM(C4), TRIM(ระยะทาง!$A:$A), 0)),IF(ISNUMBER(SEARCH("-", _xlpm.result)), 0, _xlpm.result))} -> 536.765 | E4: {=_xlfn.LET(_xlpm.result,INDEX(ระยะทาง!D:D, MATCH(TRIM($C4), TRIM(ระยะทาง!$A:$A), 0)),IF(ISNUMBER(SEARCH("-", _xlpm.result)), 0, _xlpm.result))} -> 1049852638 | F4: 132556047 | G4: 2.4987778 | H4: 536.765 | I4: 1 | J4: 8 | K4: 4.4444444 | L4: 3.714 | M4: 5 | N4: 0 | O4: 2 | P4: 10 | Q4: 5.1428571 | R4: 3.4928571 | S4: 5.0372 | T4: 0 | U4: 0 | V4: 31795.915 | W4: 14974 | X4: 46223.154 | Y4: 32681 | Z4: 18.305699 | AA4: 60.633393 | AB4: -0.035941715 | AC4: 14.665243 | AD4: =D4*'ราคาต้นทุน (Asset)'!$E$1 -> 32205900 | AE4: {=_xlfn.LET(_xlpm.result,INDEX(ASSET!U:U, MATCH(TRIM($C4), TRIM(ASSET!$A:$A), 0)),IF(ISNUMBER(SEARCH("-", _xlpm.result)), 0, _xlpm.result))} -> 2525100 | AF4: =group_data_final[[#This Row],[ค่าบำรุงจุดกางเต็นท์]]/300000 -> 2 | AG4: {=_xlfn.LET(_xlpm.result,INDEX(ราคาค่าบำรุง!D:D, MATCH(TRIM($C4), TRIM(ราคาค่าบำรุง!$A:$A), 0)),IF(ISNUMBER(SEARCH("-", _xlpm.result)), 0, _xlpm.result))} -> 600000 | AH4: =group_data_final[[#This Row],[ค่าบำรุงจุดพักรถ]]/300000 -> 0 | AI4: {=_xlfn.LET(_xlpm.result,INDEX(ราคาค่าบำรุง!F:F, MATCH(TRIM($C4), TRIM(ราคาค่าบำรุง!$A:$A), 0)),IF(ISNUMBER(SEARCH("-", _xlpm.result)), 0, _xlpm.result))} -> 0 | AJ4: =group_data_final[[#This Row],[ค่าบำรุงภูมิสถาปัตย์]]/300000 -> 0 | AK4: {=_xlfn.LET(_xlpm.result,INDEX(ราคาค่าบำรุง!H:H, MATCH(TRIM($C4), TRIM(ราคาค่าบำรุง!$A:$A), 0)),IF(ISNUMBER(SEARCH("-", _xlpm.result)), 0, _xlpm.result))} -> 0 | AL4: =IF(OR(COUNTIF(B4,"*กระบี่*"),COUNTIF(B4,"*จันทบุรี*"),COUNTIF(B4,"*ชุมพร*"),COUNTIF(B4,"*เชียงราย*"),COUNTIF(B4,"*ตรัง*"),COUNTIF(B4,"*นครนายก*"),COUNTIF(B4,"*ปราจีนบุรี*"),COUNTIF(B4,"*พัทลุง*"),COUNTIF(B4,"*ภูเก็ต*"),COUNTIF(B4,"*ยะลา*"),COUNTIF(B4,"*สกลนคร*"),COUNTIF(B4,"*สตูล*"),COUNTIF(B4,"*หนองคาย*"),COUNTIF(B4,"*สุราษฎร์ธานี*"),COUNTIF(B4,"*ปัตตานี*")),2, IF(OR(COUNTIF(B4,"*ตราด*"),COUNTIF(B4,"*นครพนม*"),COUNTIF(B4,"*นครศรีธรรมราช*"),COUNTIF(B4,"*นราธิวาส*"),COUNTIF(B4,"*บึงกาฬ*"),COUNTIF(B4,"*พังงา*"),COUNTIF(B4,"*ระนอง*"),COUNTIF(B4,"*สงขลา*")),4,0)) -> 2 | AM4: =_xlfn.XLOOKUP(group_data_final[[#This Row],[depot_code]],C:C,แผน68!D:D) -> 56319717 | AN4: 13095.525
A5: สำนักงานทางหลวงที่ 16 (นครศรีธรรมราช) | B5: ขท.พัทลุง | C5: 314 | D5: {=_xlfn.LET(_xlpm.result,INDEX(ระยะทาง!C:C, MATCH(TRIM(C5), TRIM(ระยะทาง!$A:$A), 0)),IF(ISNUMBER(SEARCH("-", _xlpm.result)), 0, _xlpm.result))} -> 585.505 | E5: {=_xlfn.LET(_xlpm.result,INDEX(ระยะทาง!D:D, MATCH(TRIM($C5), TRIM(ระยะทาง!$A:$A), 0)),IF(ISNUMBER(SEARCH("-", _xlpm.result)), 0, _xlpm.result))} -> 2304304359 | F5: 299072110 | G5: 1.969 | H5: 249.411 | I5: 2 | J5: 8 | K5: 3.7142857 | L5: 3.5 | M5: 5 | N5: 3.9 | O5: 4 | P5: 4 | Q5: 4 | R5: 3.5 | S5: 4.9375 | T5: 0 | U5: 0 | V5: 142427.25 | W5: 0 | X5: 179726.19 | Y5: 80513.558 | Z5: 30.836892 | AA5: 195.57511 | AB5: -0.03590717 | AC5: 17.145255 | AD5: =D5*'ราคาต้นทุน (Asset)'!$E$1 -> 35130300 | AE5: {=_xlfn.LET(_xlpm.result,INDEX(ASSET!U:U, MATCH(TRIM($C5), TRIM(ASSET!$A:$A), 0)),IF(ISNUMBER(SEARCH("-", _xlpm.result)), 0, _xlpm.result))} -> 2923900 | AF5: =group_data_final[[#This Row],[ค่าบำรุงจุดกางเต็นท์]]/300000 -> 0 | AG5: {=_xlfn.LET(_xlpm.result,INDEX(ราคาค่าบำรุง!D:D, MATCH(TRIM($C5), TRIM(ราคาค่าบำรุง!$A:$A), 0)),IF(ISNUMBER(SEARCH("-", _xlpm.result)), 0, _xlpm.result))} -> 0 | AH5: =group_data_final[[#This Row],[ค่าบำรุงจุดพักรถ]]/300000 -> 3 | AI5: {=_xlfn.LET(_xlpm.result,INDEX(ราคาค่าบำรุง!F:F, MATCH(TRIM($C5), TRIM(ราคาค่าบำรุง!$A:$A), 0)),IF(ISNUMBER(SEARCH("-", _xlpm.result)), 0, _xlpm.result))} -> 900000 | AJ5: =group_data_final[[#This Row],[ค่าบำรุงภูมิสถาปัตย์]]/300000 -> 0 | AK5: {=_xlfn.LET(_xlpm.result,INDEX(ราคาค่าบำรุง!H:H, MATCH(TRIM($C5), TRIM(ราคาค่าบำรุง!$A:$A), 0)),IF(ISNUMBER(SEARCH("-", _xlpm.result)), 0, _xlpm.result))} -> 0 | AL5: =IF(OR(COUNTIF(B5,"*กระบี่*"),COUNTIF(B5,"*จันทบุรี*"),COUNTIF(B5,"*ชุมพร*"),COUNTIF(B5,"*เชียงราย*"),COUNTIF(B5,"*ตรัง*"),COUNTIF(B5,"*นครนายก*"),COUNTIF(B5,"*ปราจีนบุรี*"),COUNTIF(B5,"*พัทลุง*"),COUNTIF(B5,"*ภูเก็ต*"),COUNTIF(B5,"*ยะลา*"),COUNTIF(B5,"*สกลนคร*"),COUNTIF(B5,"*สตูล*"),COUNTIF(B5,"*หนองคาย*"),COUNTIF(B5,"*สุราษฎร์ธานี*"),COUNTIF(B5,"*ปัตตานี*")),2, IF(OR(COUNTIF(B5,"*ตราด*"),COUNTIF(B5,"*นครพนม*"),COUNTIF(B5,"*นครศรีธรรมราช*"),COUNTIF(B5,"*นราธิวาส*"),COUNTIF(B5,"*บึงกาฬ*"),COUNTIF(B5,"*พังงา*"),COUNTIF(B5,"*ระนอง*"),COUNTIF(B5,"*สงขลา*")),4,0)) -> 2 | AM5: =_xlfn.XLOOKUP(group_data_final[[#This Row],[depot_code]],C:C,แผน68!D:D) -> 16076823 | AN5: 7998.2
A6: สำนักงานทางหลวงที่ 18 (สงขลา) | B6: ขท.นราธิวาส | C6: 317 | D6: {=_xlfn.LET(_xlpm.result,INDEX(ระยะทาง!C:C, MATCH(TRIM(C6), TRIM(ระยะทาง!$A:$A), 0)),IF(ISNUMBER(SEARCH("-", _xlpm.result)), 0, _xlpm.result))} -> 863.317 | E6: {=_xlfn.LET(_xlpm.result,INDEX(ระยะทาง!D:D, MATCH(TRIM($C6), TRIM(ระยะทาง!$A:$A), 0)),IF(ISNUMBER(SEARCH("-", _xlpm.result)), 0, _xlpm.result))} -> 946556998 | F6: 299063703 | G6: 2.6982222 | H6: 863.317 | I6: 1 | J6: 8 | K6: 4.4444444 | L6: 3.714 | M6: 5 | N6: 0 | O6: 2 | P6: 10 | Q6: 5.1428571 | R6: 3.4928571 | S6: 5.0372 | T6: 0 | U6: 0 | V6: 31795.915 | W6: 14974 | X6: 46223.154 | Y6: 32681 | Z6: 18.305699 | AA6: 60.633393 | AB6: -0.035941715 | AC6: 14.665243 | AD6: =D6*'ราคาต้นทุน (Asset)'!$E$1 -> 51799020 | AE6: {=_xlfn.LET(_xlpm.result,INDEX(ASSET!U:U, MATCH(TRIM($C6), TRIM(ASSET!$A:$A), 0)),IF(ISNUMBER(SEARCH("-", _xlpm.result)), 0, _xlpm.result))} -> 3634700 | AF6: =group_data_final[[#This Row],[ค่าบำรุงจุดกางเต็นท์]]/300000 -> 0 | AG6: {=_xlfn.LET(_xlpm.result,INDEX(ราคาค่าบำรุง!D:D, MATCH(TRIM($C6), TRIM(ราคาค่าบำรุง!$A:$A), 0)),IF(ISNUMBER(SEARCH("-", _xlpm.result)), 0, _xlpm.result))} -> 0 | AH6: =group_data_final[[#This Row],[ค่าบำรุงจุดพักรถ]]/300000 -> 0 | AI6: {=_xlfn.LET(_xlpm.result,INDEX(ราคาค่าบำรุง!F:F, MATCH(TRIM($C6), TRIM(ราคาค่าบำรุง!$A:$A), 0)),IF(ISNUMBER(SEARCH("-", _xlpm.result)), 0, _xlpm.result))} -> 0 | AJ6: =group_data_final[[#This Row],[ค่าบำรุงภูมิสถาปัตย์]]/300000 -> 0 | AK6: {=_xlfn.LET(_xlpm.result,INDEX(ราคาค่าบำรุง!H:H, MATCH(TRIM($C6), TRIM(ราคาค่าบำรุง!$A:$A), 0)),IF(ISNUMBER(SEARCH("-", _xlpm.result)), 0, _xlpm.result))} -> 0 | AL6: =IF(OR(COUNTIF(B6,"*กระบี่*"),COUNTIF(B6,"*จันทบุรี*"),COUNTIF(B6,"*ชุมพร*"),COUNTIF(B6,"*เชียงราย*"),COUNTIF(B6,"*ตรัง*"),COUNTIF(B6,"*นครนายก*"),COUNTIF(B6,"*ปราจีนบุรี*"),COUNTIF(B6,"*พัทลุง*"),COUNTIF(B6,"*ภูเก็ต*"),COUNTIF(B6,"*ยะลา*"),COUNTIF(B6,"*สกลนคร*"),COUNTIF(B6,"*สตูล*"),COUNTIF(B6,"*หนองคาย*"),COUNTIF(B6,"*สุราษฎร์ธานี*"),COUNTIF(B6,"*ปัตตานี*")),2, IF(OR(COUNTIF(B6,"*ตราด*"),COUNTIF(B6,"*นครพนม*"),COUNTIF(B6,"*นครศรีธรรมราช*"),COUNTIF(B6,"*นราธิวาส*"),COUNTIF(B6,"*บึงกาฬ*"),COUNTIF(B6,"*พังงา*"),COUNTIF(B6,"*ระนอง*"),COUNTIF(B6,"*สงขลา*")),4,0)) -> 4 | AM6: =_xlfn.XLOOKUP(group_data_final[[#This Row],[depot_code]],C:C,แผน68!D:D) -> 38452908 | AN6: 14423.5
A7: สำนักงานทางหลวงที่ 18 (สงขลา) | B7: ขท.สตูล | C7: 318 | D7: {=_xlfn.LET(_xlpm.result,INDEX(ระยะทาง!C:C, MATCH(TRIM(C7), TRIM(ระยะทาง!$A:$A), 0)),IF(ISNUMBER(SEARCH("-", _xlpm.result)), 0, _xlpm.result))} -> 518.552 | E7: {=_xlfn.LET(_xlpm.result,INDEX(ระยะทาง!D:D, MATCH(TRIM($C7), TRIM(ระยะทาง!$A:$A), 0)),IF(ISNUMBER(SEARCH("-", _xlpm.result)), 0, _xlpm.result))} -> 950402637 | F7: 321027467 | G7: 2.4987778 | H7: 356.032 | I7: 2 | J7: 6 | K7: 3.1111111 | L7: 3.5 | M7: 5 | N7: 9.478 | O7: 4 | P7: 4 | Q7: 4 | R7: 3.4443333 | S7: 5.2 | T7: 0 | U7: 0 | V7: 105579.08 | W7: 686.9 | X7: 52829.42 | Y7: 71561 | Z7: 23.183759 | AA7: 179.18493 | AB7: -0.4617204 | AC7: 36.432521 | AD7: =D7*'ราคาต้นทุน (Asset)'!$E$1 -> 31113120 | AE7: {=_xlfn.LET(_xlpm.result,INDEX(ASSET!U:U, MATCH(TRIM($C7), TRIM(ASSET!$A:$A), 0)),IF(ISNUMBER(SEARCH("-", _xlpm.result)), 0, _xlpm.result))} -> 3423700 | AF7: =group_data_final[[#This Row],[ค่าบำรุงจุดกางเต็นท์]]/300000 -> 0 | AG7: {=_xlfn.LET(_xlpm.result,INDEX(ราคาค่าบำรุง!D:D, MATCH(TRIM($C7), TRIM(ราคาค่าบำรุง!$A:$A), 0)),IF(ISNUMBER(SEARCH("-", _xlpm.result)), 0, _xlpm.result))} -> 0 | AH7: =group_data_final[[#This Row],[ค่าบำรุงจุดพักรถ]]/300000 -> 0 | AI7: {=_xlfn.LET(_xlpm.result,INDEX(ราคาค่าบำรุง!F:F, MATCH(TRIM($C7), TRIM(ราคาค่าบำรุง!$A:$A), 0)),IF(ISNUMBER(SEARCH("-", _xlpm.result)), 0, _xlpm.result))} -> 0 | AJ7: =group_data_final[[#This Row],[ค่าบำรุงภูมิสถาปัตย์]]/300000 -> 0 | AK7: {=_xlfn.LET(_xlpm.result,INDEX(ราคาค่าบำรุง!H:H, MATCH(TRIM($C7), TRIM(ราคาค่าบำรุง!$A:$A), 0)),IF(ISNUMBER(SEARCH("-", _xlpm.result)), 0, _xlpm.result))} -> 0 | AL7: =IF(OR(COUNTIF(B7,"*กระบี่*"),COUNTIF(B7,"*จันทบุรี*"),COUNTIF(B7,"*ชุมพร*"),COUNTIF(B7,"*เชียงราย*"),COUNTIF(B7,"*ตรัง*"),COUNTIF(B7,"*นครนายก*"),COUNTIF(B7,"*ปราจีนบุรี*"),COUNTIF(B7,"*พัทลุง*"),COUNTIF(B7,"*ภูเก็ต*"),COUNTIF(B7,"*ยะลา*"),COUNTIF(B7,"*สกลนคร*"),COUNTIF(B7,"*สตูล*"),COUNTIF(B7,"*หนองคาย*"),COUNTIF(B7,"*สุราษฎร์ธานี*"),COUNTIF(B7,"*ปัตตานี*")),2, IF(OR(COUNTIF(B7,"*ตราด*"),COUNTIF(B7,"*นครพนม*"),COUNTIF(B7,"*นครศรีธรรมราช*"),COUNTIF(B7,"*นราธิวาส*"),COUNTIF(B7,"*บึงกาฬ*"),COUNTIF(B7,"*พังงา*"),COUNTIF(B7,"*ระนอง*"),COUNTIF(B7,"*สงขลา*")),4,0)) -> 2 | AM7: =_xlfn.XLOOKUP(group_data_final[[#This Row],[depot_code]],C:C,แผน68!D:D) -> 35219242 | AN7: 2927
A8: สำนักงานทางหลวงที่ 18 (สงขลา) | B8: ขท.สงขลาที่ 2 (นาหม่อม) | C8: 319 | D8: {=_xlfn.LET(_xlpm.result,INDEX(ระยะทาง!C:C, MATCH(TRIM(C8), TRIM(ระยะทาง!$A:$A), 0)),IF(ISNUMBER(SEARCH("-", _xlpm.result)), 0, _xlpm.result))} -> 512.757 | E8: {=_xlfn.LET(_xlpm.result,INDEX(ระยะทาง!D:D, MATCH(TRIM($C8), TRIM(ระยะทาง!$A:$A), 0)),IF(ISNUMBER(SEARCH("-", _xlpm.result)), 0, _xlpm.result))} -> 1249744605 | F8: 436037927 | G8: 2.4987778 | H8: 512.757 | I8: 1 | J8: 8 | K8: 4.4444444 | L8: 3.714 | M8: 5 | N8: 0 | O8: 2 | P8: 10 | Q8: 5.1428571 | R8: 3.4928571 | S8: 5.0372 | T8: 0 | U8: 0 | V8: 31795.915 | W8: 14974 | X8: 46223.154 | Y8: 32681 | Z8: 18.305699 | AA8: 60.633393 | AB8: -0.035941715 | AC8: 14.665243 | AD8: =D8*'ราคาต้นทุน (Asset)'!$E$1 -> 30765420 | AE8: {=_xlfn.LET(_xlpm.result,INDEX(ASSET!U:U, MATCH(TRIM($C8), TRIM(ASSET!$A:$A), 0)),IF(ISNUMBER(SEARCH("-", _xlpm.result)), 0, _xlpm.result))} -> 2094200 | AF8: =group_data_final[[#This Row],[ค่าบำรุงจุดกางเต็นท์]]/300000 -> 0 | AG8: {=_xlfn.LET(_xlpm.result,INDEX(ราคาค่าบำรุง!D:D, MATCH(TRIM($C8), TRIM(ราคาค่าบำรุง!$A:$A), 0)),IF(ISNUMBER(SEARCH("-", _xlpm.result)), 0, _xlpm.result))} -> 0 | AH8: =group_data_final[[#This Row],[ค่าบำรุงจุดพักรถ]]/300000 -> 1 | AI8: {=_xlfn.LET(_xlpm.result,INDEX(ราคาค่าบำรุง!F:F, MATCH(TRIM($C8), TRIM(ราคาค่าบำรุง!$A:$A), 0)),IF(ISNUMBER(SEARCH("-", _xlpm.result)), 0, _xlpm.result))} -> 300000 | AJ8: =group_data_final[[#This Row],[ค่าบำรุงภูมิสถาปัตย์]]/300000 -> 0 | AK8: {=_xlfn.LET(_xlpm.result,INDEX(ราคาค่าบำรุง!H:H, MATCH(TRIM($C8), TRIM(ราคาค่าบำรุง!$A:$A), 0)),IF(ISNUMBER(SEARCH("-", _xlpm.result)), 0, _xlpm.result))} -> 0 | AL8: =IF(OR(COUNTIF(B8,"*กระบี่*"),COUNTIF(B8,"*จันทบุรี*"),COUNTIF(B8,"*ชุมพร*"),COUNTIF(B8,"*เชียงราย*"),COUNTIF(B8,"*ตรัง*"),COUNTIF(B8,"*นครนายก*"),COUNTIF(B8,"*ปราจีนบุรี*"),COUNTIF(B8,"*พัทลุง*"),COUNTIF(B8,"*ภูเก็ต*"),COUNTIF(B8,"*ยะลา*"),COUNTIF(B8,"*สกลนคร*"),COUNTIF(B8,"*สตูล*"),COUNTIF(B8,"*หนองคาย*"),COUNTIF(B8,"*สุราษฎร์ธานี*"),COUNTIF(B8,"*ปัตตานี*")),2, IF(OR(COUNTIF(B8,"*ตราด*"),COUNTIF(B8,"*นครพนม*"),COUNTIF(B8,"*นครศรีธรรมราช*"),COUNTIF(B8,"*นราธิวาส*"),COUNTIF(B8,"*บึงกาฬ*"),COUNTIF(B8,"*พังงา*"),COUNTIF(B8,"*ระนอง*"),COUNTIF(B8,"*สงขลา*")),4,0)) -> 4 | AM8: =_xlfn.XLOOKUP(group_data_final[[#This Row],[depot_code]],C:C,แผน68!D:D) -> 15992686 | AN8: 5798.7
A9: สำนักงานทางหลวงที่ 16 (นครศรีธรรมราช) | B9: ขท.นครศรีธรรมราชที่ 1 | C9: 321 | D9: {=_xlfn.LET(_xlpm.result,INDEX(ระยะทาง!C:C, MATCH(TRIM(C9), TRIM(ระยะทาง!$A:$A), 0)),IF(ISNUMBER(SEARCH("-", _xlpm.result)), 0, _xlpm.result))} -> 824.601 | E9: {=_xlfn.LET(_xlpm.result,INDEX(ระยะทาง!D:D, MATCH(TRIM($C9), TRIM(ระยะทาง!$A:$A), 0)),IF(ISNUMBER(SEARCH("-", _xlpm.result)), 0, _xlpm.result))} -> 456253646 | F9: 395057101 | G9: 2.1472857 | H9: 522.041 | I9: 2 | J9: 6 | K9: 3.2857143 | L9: 3.5 | M9: 5 | N9: 11.62 | O9: 2 | P9: 6 | Q9: 3.8 | R9: 3.5 | S9: 5 | T9: 0 | U9: 0 | V9: 281391.29 | W9: 43702.56 | X9: 141960.01 | Y9: 196273.2 | Z9: 21.336416 | AA9: 211.89182 | AB9: 0.098783852 | AC9: 22.083402 | AD9: =D9*'ราคาต้นทุน (Asset)'!$E$1 -> 49476060 | AE9: {=_xlfn.LET(_xlpm.result,INDEX(ASSET!U:U, MATCH(TRIM($C9), TRIM(ASSET!$A:$A), 0)),IF(ISNUMBER(SEARCH("-", _xlpm.result)), 0, _xlpm.result))} -> 4386300 | AF9: =group_data_final[[#This Row],[ค่าบำรุงจุดกางเต็นท์]]/300000 -> 1 | AG9: {=_xlfn.LET(_xlpm.result,INDEX(ราคาค่าบำรุง!D:D, MATCH(TRIM($C9), TRIM(ราคาค่าบำรุง!$A:$A), 0)),IF(ISNUMBER(SEARCH("-", _xlpm.result)), 0, _xlpm.result))} -> 300000 | AH9: =group_data_final[[#This Row],[ค่าบำรุงจุดพักรถ]]/300000 -> 3 | AI9: {=_xlfn.LET(_xlpm.result,INDEX(ราคาค่าบำรุง!F:F, MATCH(TRIM($C9), TRIM(ราคาค่าบำรุง!$A:$A), 0)),IF(ISNUMBER(SEARCH("-", _xlpm.result)), 0, _xlpm.result))} -> 900000 | AJ9: =group_data_final[[#This Row],[ค่าบำรุงภูมิสถาปัตย์]]/300000 -> 0 | AK9: {=_xlfn.LET(_xlpm.result,INDEX(ราคาค่าบำรุง!H:H, MATCH(TRIM($C9), TRIM(ราคาค่าบำรุง!$A:$A), 0)),IF(ISNUMBER(SEARCH("-", _xlpm.result)), 0, _xlpm.result))} -> 0 | AL9: =IF(OR(COUNTIF(B9,"*กระบี่*"),COUNTIF(B9,"*จันทบุรี*"),COUNTIF(B9,"*ชุมพร*"),COUNTIF(B9,"*เชียงราย*"),COUNTIF(B9,"*ตรัง*"),COUNTIF(B9,"*นครนายก*"),COUNTIF(B9,"*ปราจีนบุรี*"),COUNTIF(B9,"*พัทลุง*"),COUNTIF(B9,"*ภูเก็ต*"),COUNTIF(B9,"*ยะลา*"),COUNTIF(B9,"*สกลนคร*"),COUNTIF(B9,"*สตูล*"),COUNTIF(B9,"*หนองคาย*"),COUNTIF(B9,"*สุราษฎร์ธานี*"),COUNTIF(B9,"*ปัตตานี*")),2, IF(OR(COUNTIF(B9,"*ตราด*"),COUNTIF(B9,"*นครพนม*"),COUNTIF(B9,"*นครศรีธรรมราช*"),COUNTIF(B9,"*นราธิวาส*"),COUNTIF(B9,"*บึงกาฬ*"),COUNTIF(B9,"*พังงา*"),COUNTIF(B9,"*ระนอง*"),COUNTIF(B9,"*สงขลา*")),4,0)) -> 4 | AM9: =_xlfn.XLOOKUP(group_data_final[[#This Row],[depot_code]],C:C,แผน68!D:D) -> 20146537 | AN9: 16169.3
A10: สำนักงานทางหลวงที่ 17 (กระบี่) | B10: ขท.ตรัง | C10: 322 | D10: {=_xlfn.LET(_xlpm.result,INDEX(ระยะทาง!C:C, MATCH(TRIM(C10), TRIM(ระยะทาง!$A:$A), 0)),IF(ISNUMBER(SEARCH("-", _xlpm.result)), 0, _xlpm.result))} -> 781.685 | E10: {=_xlfn.LET(_xlpm.result,INDEX(ระยะทาง!D:D, MATCH(TRIM($C10), TRIM(ระยะทาง!$A:$A), 0)),IF(ISNUMBER(SEARCH("-", _xlpm.result)), 0, _xlpm.result))} -> 852306494 | F10: 292790676 | G10: 2.258875 | H10: 422.069 | I10: 2 | J10: 6 | K10: 3.25 | L10: 3.5 | M10: 5 | N10: 56.118 | O10: 4 | P10: 6 | Q10: 4.3636364 | R10: 3.5 | S10: 4.7272727 | T10: 157.4676 | U10: 0 | V10: 330600.03 | W10: 37525.04 | X10: 187080.31 | Y10: 175107.56 | Z10: 34.601979 | AA10: 276.6916 | AB10: 0.040175278 | AC10: 29.419706 | AD10: =D10*'ราคาต้นทุน (Asset)'!$E$1 -> 46901100 | AE10: {=_xlfn.LET(_xlpm.result,INDEX(ASSET!U:U, MATCH(TRIM($C10), TRIM(ASSET!$A:$A), 0)),IF(ISNUMBER(SEARCH("-", _xlpm.result)), 0, _xlpm.result))} -> 4125700 | AF10: =group_data_final[[#This Row],[ค่าบำรุงจุดกางเต็นท์]]/300000 -> 1 | AG10: {=_xlfn.LET(_xlpm.result,INDEX(ราคาค่าบำรุง!D:D, MATCH(TRIM($C10), TRIM(ราคาค่าบำรุง!$A:$A), 0)),IF(ISNUMBER(SEARCH("-", _xlpm.result)), 0, _xlpm.result))} -> 300000 | AH10: =group_data_final[[#This Row],[ค่าบำรุงจุดพักรถ]]/300000 -> 3 | AI10: {=_xlfn.LET(_xlpm.result,INDEX(ราคาค่าบำรุง!F:F, MATCH(TRIM($C10), TRIM(ราคาค่าบำรุง!$A:$A), 0)),IF(ISNUMBER(SEARCH("-", _xlpm.result)), 0, _xlpm.result))} -> 900000 | AJ10: =group_data_final[[#This Row],[ค่าบำรุงภูมิสถาปัตย์]]/300000 -> 0 | AK10: {=_xlfn.LET(_xlpm.result,INDEX(ราคาค่าบำรุง!H:H, MATCH(TRIM($C10), TRIM(ราคาค่าบำรุง!$A:$A), 0)),IF(ISNUMBER(SEARCH("-", _xlpm.result)), 0, _xlpm.result))} -> 0 | AL10: =IF(OR(COUNTIF(B10,"*กระบี่*"),COUNTIF(B10,"*จันทบุรี*"),COUNTIF(B10,"*ชุมพร*"),COUNTIF(B10,"*เชียงราย*"),COUNTIF(B10,"*ตรัง*"),COUNTIF(B10,"*นครนายก*"),COUNTIF(B10,"*ปราจีนบุรี*"),COUNTIF(B10,"*พัทลุง*"),COUNTIF(B10,"*ภูเก็ต*"),COUNTIF(B10,"*ยะลา*"),COUNTIF(B10,"*สกลนคร*"),COUNTIF(B10,"*สตูล*"),COUNTIF(B10,"*หนองคาย*"),COUNTIF(B10,"*สุราษฎร์ธานี*"),COUNTIF(B10,"*ปัตตานี*")),2, IF(OR(COUNTIF(B10,"*ตราด*"),COUNTIF(B10,"*นครพนม*"),COUNTIF(B10,"*นครศรีธรรมราช*"),COUNTIF(B10,"*นราธิวาส*"),COUNTIF(B10,"*บึงกาฬ*"),COUNTIF(B10,"*พังงา*"),COUNTIF(B10,"*ระนอง*"),COUNTIF(B10,"*สงขลา*")),4,0)) -> 2 | AM10: =_xlfn.XLOOKUP(group_data_final[[#This Row],[depot_code]],C:C,แผน68!D:D) -> 13871167 | AN10: 7842.6
A11: สำนักงานทางหลวงที่ 17 (กระบี่) | B11: ขท.กระบี่ | C11: 323 | D11: {=_xlfn.LET(_xlpm.result,INDEX(ระยะทาง!C:C, MATCH(TRIM(C11), TRIM(ระยะทาง!$A:$A), 0)),IF(ISNUMBER(SEARCH("-", _xlpm.result)), 0, _xlpm.result))} -> 752.712 | E11: {=_xlfn.LET(_xlpm.result,INDEX(ระยะทาง!D:D, MATCH(TRIM($C11), TRIM(ระยะทาง!$A:$A), 0)),IF(ISNUMBER(SEARCH("-", _xlpm.result)), 0, _xlpm.result))} -> 3359867039 | F11: 164262761 | G11: 2.3249 | H11: 377.016 | I11: 2 | J11: 8 | K11: 3.8 | L11: 3.5 | M11: 5 | N11: 6.803 | O11: 6 | P11: 8 | Q11: 7.5 | T11: 0 | U11: 0 | V11: 117197.82 | W11: 11469.8 | X11: 154243.36 | Y11: 128960 | Z11: 38.839194 | AA11: 283.53395 | AB11: 0.015192977 | AC11: 32.891799 | AD11: =D11*'ราคาต้นทุน (Asset)'!$E$1 -> 45162720 | AE11: {=_xlfn.LET(_xlpm.result,INDEX(ASSET!U:U, MATCH(TRIM($C11), TRIM(ASSET!$A:$A), 0)),IF(ISNUMBER(SEARCH("-", _xlpm.result)), 0, _xlpm.result))} -> 3235000 | AF11: =group_data_final[[#This Row],[ค่าบำรุงจุดกางเต็นท์]]/300000 -> 0 | AG11: {=_xlfn.LET(_xlpm.result,INDEX(ราคาค่าบำรุง!D:D, MATCH(TRIM($C11), TRIM(ราคาค่าบำรุง!$A:$A), 0)),IF(ISNUMBER(SEARCH("-", _xlpm.result)), 0, _xlpm.result))} -> 0 | AH11: =group_data_final[[#This Row],[ค่าบำรุงจุดพักรถ]]/300000 -> 0 | AI11: {=_xlfn.LET(_xlpm.result,INDEX(ราคาค่าบำรุง!F:F, MATCH(TRIM($C11), TRIM(ราคาค่าบำรุง!$A:$A), 0)),IF(ISNUMBER(SEARCH("-", _xlpm.result)), 0, _xlpm.result))} -> 0 | AJ11: =group_data_final[[#This Row],[ค่าบำรุงภูมิสถาปัตย์]]/300000 -> 5 | AK11: {=_xlfn.LET(_xlpm.result,INDEX(ราคาค่าบำรุง!H:H, MATCH(TRIM($C11), TRIM(ราคาค่าบำรุง!$A:$A), 0)),IF(ISNUMBER(SEARCH("-", _xlpm.result)), 0, _xlpm.result))} -> 1500000 | AL11: =IF(OR(COUNTIF(B11,"*กระบี่*"),COUNTIF(B11,"*จันทบุรี*"),COUNTIF(B11,"*ชุมพร*"),COUNTIF(B11,"*เชียงราย*"),COUNTIF(B11,"*ตรัง*"),COUNTIF(B11,"*นครนายก*"),COUNTIF(B11,"*ปราจีนบุรี*"),COUNTIF(B11,"*พัทลุง*"),COUNTIF(B11,"*ภูเก็ต*"),COUNTIF(B11,"*ยะลา*"),COUNTIF(B11,"*สกลนคร*"),COUNTIF(B11,"*สตูล*"),COUNTIF(B11,"*หนองคาย*"),COUNTIF(B11,"*สุราษฎร์ธานี*"),COUNTIF(B11,"*ปัตตานี*")),2, IF(OR(COUNTIF(B11,"*ตราด*"),COUNTIF(B11,"*นครพนม*"),COUNTIF(B11,"*นครศรีธรรมราช*"),COUNTIF(B11,"*นราธิวาส*"),COUNTIF(B11,"*บึงกาฬ*"),COUNTIF(B11,"*พังงา*"),COUNTIF(B11,"*ระนอง*"),COUNTIF(B11,"*สงขลา*")),4,0)) -> 2 | AM11: =_xlfn.XLOOKUP(group_data_final[[#This Row],[depot_code]],C:C,แผน68!D:D) -> 9306767.8 | AN11: 4899.5
A12: สำนักงานทางหลวงที่ 17 (กระบี่) | B12: ขท.ภูเก็ต | C12: 324 | D12: {=_xlfn.LET(_xlpm.result,INDEX(ระยะทาง!C:C, MATCH(TRIM(C12), TRIM(ระยะทาง!$A:$A), 0)),IF(ISNUMBER(SEARCH("-", _xlpm.result)), 0, _xlpm.result))} -> 603.141 | E12: {=_xlfn.LET(_xlpm.result,INDEX(ระยะทาง!D:D, MATCH(TRIM($C12), TRIM(ระยะทาง!$A:$A), 0)),IF(ISNUMBER(SEARCH("-", _xlpm.result)), 0, _xlpm.result))} -> 2002651336 | F12: 286100492 | G12: 2.1375 | H12: 183.826 | I12: 2 | J12: 6 | K12: 3.75 | L12: 3.5 | M12: 5.142 | N12: 1.41 | O12: 6 | P12: 6 | Q12: 6 | R12: 3.5 | S12: 4 | T12: 84454.5 | U12: 0 | V12: 183292.9 | W12: 298.6 | X12: 77498.53 | Y12: 76414 | Z12: 18.8077 | AA12: 236.84713 | AB12: 0.060811905 | AC12: 40.625832 | AD12: =D12*'ราคาต้นทุน (Asset)'!$E$1 -> 36188460 | AE12: {=_xlfn.LET(_xlpm.result,INDEX(ASSET!U:U, MATCH(TRIM($C12), TRIM(ASSET!$A:$A), 0)),IF(ISNUMBER(SEARCH("-", _xlpm.result)), 0, _xlpm.result))} -> 4392300 | AF12: =group_data_final[[#This Row],[ค่าบำรุงจุดกางเต็นท์]]/300000 -> 0 | AG12: {=_xlfn.LET(_xlpm.result,INDEX(ราคาค่าบำรุง!D:D, MATCH(TRIM($C12), TRIM(ราคาค่าบำรุง!$A:$A), 0)),IF(ISNUMBER(SEARCH("-", _xlpm.result)), 0, _xlpm.result))} -> 0 | AH12: =group_data_final[[#This Row],[ค่าบำรุงจุดพักรถ]]/300000 -> 9 | AI12: {=_xlfn.LET(_xlpm.result,INDEX(ราคาค่าบำรุง!F:F, MATCH(TRIM($C12), TRIM(ราคาค่าบำรุง!$A:$A), 0)),IF(ISNUMBER(SEARCH("-", _xlpm.result)), 0, _xlpm.result))} -> 2700000 | AJ12: =group_data_final[[#This Row],[ค่าบำรุงภูมิสถาปัตย์]]/300000 -> 2 | AK12: {=_xlfn.LET(_xlpm.result,INDEX(ราคาค่าบำรุง!H:H, MATCH(TRIM($C12), TRIM(ราคาค่าบำรุง!$A:$A), 0)),IF(ISNUMBER(SEARCH("-", _xlpm.result)), 0, _xlpm.result))} -> 600000 | AL12: =IF(OR(COUNTIF(B12,"*กระบี่*"),COUNTIF(B12,"*จันทบุรี*"),COUNTIF(B12,"*ชุมพร*"),COUNTIF(B12,"*เชียงราย*"),COUNTIF(B12,"*ตรัง*"),COUNTIF(B12,"*นครนายก*"),COUNTIF(B12,"*ปราจีนบุรี*"),COUNTIF(B12,"*พัทลุง*"),COUNTIF(B12,"*ภูเก็ต*"),COUNTIF(B12,"*ยะลา*"),COUNTIF(B12,"*สกลนคร*"),COUNTIF(B12,"*สตูล*"),COUNTIF(B12,"*หนองคาย*"),COUNTIF(B12,"*สุราษฎร์ธานี*"),COUNTIF(B12,"*ปัตตานี*")),2, IF(OR(COUNTIF(B12,"*ตราด*"),COUNTIF(B12,"*นครพนม*"),COUNTIF(B12,"*นครศรีธรรมราช*"),COUNTIF(B12,"*นราธิวาส*"),COUNTIF(B12,"*บึงกาฬ*"),COUNTIF(B12,"*พังงา*"),COUNTIF(B12,"*ระนอง*"),COUNTIF(B12,"*สงขลา*")),4,0)) -> 2 | AM12: =_xlfn.XLOOKUP(group_data_final[[#This Row],[depot_code]],C:C,แผน68!D:D) -> 17236877 | AN12: 3881.05
A13: สำนักงานทางหลวงที่ 16 (นครศรีธรรมราช) | B13: ขท.สุราษฎร์ธานีที่ 1 | C13: 325 | D13: {=_xlfn.LET(_xlpm.result,INDEX(ระยะทาง!C:C, MATCH(TRIM(C13), TRIM(ระยะทาง!$A:$A), 0)),IF(ISNUMBER(SEARCH("-", _xlpm.result)), 0, _xlpm.result))} -> 837.591 | E13: {=_xlfn.LET(_xlpm.result,INDEX(ระยะทาง!D:D, MATCH(TRIM($C13), TRIM(ระยะทาง!$A:$A), 0)),IF(ISNUMBER(SEARCH("-", _xlpm.result)), 0, _xlpm.result))} -> 1428980582 | F13: 340339410 | G13: 2.888 | H13: 336.702 | I13: 4 | J13: 10 | K13: 4.75 | L13: 3.5 | M13: 5 | N13: 28.52 | O13: 4 | P13: 8 | Q13: 5.25 | R13: 3.9834 | S13: 5.1 | T13: 0 | U13: 0 | V13: 104749.26 | W13: 22826.2 | X13: 161539.41 | Y13: 67464.56 | Z13: 25.816613 | AA13: 195.01159 | AB13: 0.0087856958 | AC13: 21.360564 | AD13: =D13*'ราคาต้นทุน (Asset)'!$E$1 -> 50255460 | AE13: {=_xlfn.LET(_xlpm.result,INDEX(ASSET!U:U, MATCH(TRIM($C13), TRIM(ASSET!$A:$A), 0)),IF(ISNUMBER(SEARCH("-", _xlpm.result)), 0, _xlpm.result))} -> 3374200 | AF13: =group_data_final[[#This Row],[ค่าบำรุงจุดกางเต็นท์]]/300000 -> 2 | AG13: {=_xlfn.LET(_xlpm.result,INDEX(ราคาค่าบำรุง!D:D, MATCH(TRIM($C13), TRIM(ราคาค่าบำรุง!$A:$A), 0)),IF(ISNUMBER(SEARCH("-", _xlpm.result)), 0, _xlpm.result))} -> 600000 | AH13: =group_data_final[[#This Row],[ค่าบำรุงจุดพักรถ]]/300000 -> 0 | AI13: {=_xlfn.LET(_xlpm.result,INDEX(ราคาค่าบำรุง!F:F, MATCH(TRIM($C13), TRIM(ราคาค่าบำรุง!$A:$A), 0)),IF(ISNUMBER(SEARCH("-", _xlpm.result)), 0, _xlpm.result))} -> 0 | AJ13: =group_data_final[[#This Row],[ค่าบำรุงภูมิสถาปัตย์]]/300000 -> 0 | AK13: {=_xlfn.LET(_xlpm.result,INDEX(ราคาค่าบำรุง!H:H, MATCH(TRIM($C13), TRIM(ราคาค่าบำรุง!$A:$A), 0)),IF(ISNUMBER(SEARCH("-", _xlpm.result)), 0, _xlpm.result))} -> 0 | AL13: =IF(OR(COUNTIF(B13,"*กระบี่*"),COUNTIF(B13,"*จันทบุรี*"),COUNTIF(B13,"*ชุมพร*"),COUNTIF(B13,"*เชียงราย*"),COUNTIF(B13,"*ตรัง*"),COUNTIF(B13,"*นครนายก*"),COUNTIF(B13,"*ปราจีนบุรี*"),COUNTIF(B13,"*พัทลุง*"),COUNTIF(B13,"*ภูเก็ต*"),COUNTIF(B13,"*ยะลา*"),COUNTIF(B13,"*สกลนคร*"),COUNTIF(B13,"*สตูล*"),COUNTIF(B13,"*หนองคาย*"),COUNTIF(B13,"*สุราษฎร์ธานี*"),COUNTIF(B13,"*ปัตตานี*")),2, IF(OR(COUNTIF(B13,"*ตราด*"),COUNTIF(B13,"*นครพนม*"),COUNTIF(B13,"*นครศรีธรรมราช*"),COUNTIF(B13,"*นราธิวาส*"),COUNTIF(B13,"*บึงกาฬ*"),COUNTIF(B13,"*พังงา*"),COUNTIF(B13,"*ระนอง*"),COUNTIF(B13,"*สงขลา*")),4,0)) -> 2 | AM13: =_xlfn.XLOOKUP(group_data_final[[#This Row],[depot_code]],C:C,แผน68!D:D) -> 47805316 | AN13: 19521.95
A14: สำนักงานทางหลวงที่ 16 (นครศรีธรรมราช) | B14: ขท.นครศรีธรรมราชที่ 2 (ทุ่งสง) | C14: 326 | D14: {=_xlfn.LET(_xlpm.result,INDEX(ระยะทาง!C:C, MATCH(TRIM(C14), TRIM(ระยะทาง!$A:$A), 0)),IF(ISNUMBER(SEARCH("-", _xlpm.result)), 0, _xlpm.result))} -> 796.763 | E14: {=_xlfn.LET(_xlpm.result,INDEX(ระยะทาง!D:D, MATCH(TRIM($C14), TRIM(ระยะทาง!$A:$A), 0)),IF(ISNUMBER(SEARCH("-", _xlpm.result)), 0, _xlpm.result))} -> 1652487745 | F14: 117360950 | G14: 2.047 | H14: 336.505 | I14: 1 | J14: 8 | K14: 3.6666667 | L14: 3.633 | M14: 5 | N14: 4.637 | O14: 1 | P14: 4 | Q14: 2.75 | R14: 3.5 | T14: 0 | U14: 0 | V14: 201275.85 | W14: 20481.05 | X14: 67600.845 | Y14: 130569.13 | Z14: 44.054685 | AA14: 299.71773 | AB14: -0.0102959 | AC14: 29.336213 | AD14: =D14*'ราคาต้นทุน (Asset)'!$E$1 -> 47805780 | AE14: {=_xlfn.LET(_xlpm.result,INDEX(ASSET!U:U, MATCH(TRIM($C14), TRIM(ASSET!$A:$A), 0)),IF(ISNUMBER(SEARCH("-", _xlpm.result)), 0, _xlpm.result))} -> 3582200 | AF14: =group_data_final[[#This Row],[ค่าบำรุงจุดกางเต็นท์]]/300000 -> 0 | AG14: {=_xlfn.LET(_xlpm.result,INDEX(ราคาค่าบำรุง!D:D, MATCH(TRIM($C14), TRIM(ราคาค่าบำรุง!$A:$A), 0)),IF(ISNUMBER(SEARCH("-", _xlpm.result)), 0, _xlpm.result))} -> 0 | AH14: =group_data_final[[#This Row],[ค่าบำรุงจุดพักรถ]]/300000 -> 1 | AI14: {=_xlfn.LET(_xlpm.result,INDEX(ราคาค่าบำรุง!F:F, MATCH(TRIM($C14), TRIM(ราคาค่าบำรุง!$A:$A), 0)),IF(ISNUMBER(SEARCH("-", _xlpm.result)), 0, _xlpm.result))} -> 300000 | AJ14: =group_data_final[[#This Row],[ค่าบำรุงภูมิสถาปัตย์]]/300000 -> 2 | AK14: {=_xlfn.LET(_xlpm.result,INDEX(ราคาค่าบำรุง!H:H, MATCH(TRIM($C14), TRIM(ราคาค่าบำรุง!$A:$A), 0)),IF(ISNUMBER(SEARCH("-", _xlpm.result)), 0, _xlpm.result))} -> 600000 | AL14: =IF(OR(COUNTIF(B14,"*กระบี่*"),COUNTIF(B14,"*จันทบุรี*"),COUNTIF(B14,"*ชุมพร*"),COUNTIF(B14,"*เชียงราย*"),COUNTIF(B14,"*ตรัง*"),COUNTIF(B14,"*นครนายก*"),COUNTIF(B14,"*ปราจีนบุรี*"),COUNTIF(B14,"*พัทลุง*"),COUNTIF(B14,"*ภูเก็ต*"),COUNTIF(B14,"*ยะลา*"),COUNTIF(B14,"*สกลนคร*"),COUNTIF(B14,"*สตูล*"),COUNTIF(B14,"*หนองคาย*"),COUNTIF(B14,"*สุราษฎร์ธานี*"),COUNTIF(B14,"*ปัตตานี*")),2, IF(OR(COUNTIF(B14,"*ตราด*"),COUNTIF(B14,"*นครพนม*"),COUNTIF(B14,"*นครศรีธรรมราช*"),COUNTIF(B14,"*นราธิวาส*"),COUNTIF(B14,"*บึงกาฬ*"),COUNTIF(B14,"*พังงา*"),COUNTIF(B14,"*ระนอง*"),COUNTIF(B14,"*สงขลา*")),4,0)) -> 4 | AM14: =_xlfn.XLOOKUP(group_data_final[[#This Row],[depot_code]],C:C,แผน68!D:D) -> 46419930 | AN14: 10490.415
A15: สำนักงานทางหลวงที่ 17 (กระบี่) | B15: ขท.พังงา | C15: 327 | D15: {=_xlfn.LET(_xlpm.result,INDEX(ระยะทาง!C:C, MATCH(TRIM(C15), TRIM(ระยะทาง!$A:$A), 0)),IF(ISNUMBER(SEARCH("-", _xlpm.result)), 0, _xlpm.result))} -> 631.11 | E15: {=_xlfn.LET(_xlpm.result,INDEX(ระยะทาง!D:D, MATCH(TRIM($C15), TRIM(ระยะทาง!$A:$A), 0)),IF(ISNUMBER(SEARCH("-", _xlpm.result)), 0, _xlpm.result))} -> 1037823437 | F15: 147135214 | G15: 2.26175 | H15: 351.789 | I15: 2 | J15: 8 | K15: 3.625 | L15: 3.5 | M15: 5 | N15: 4.798 | O15: 4 | P15: 4 | Q15: 4 | R15: 3.5 | S15: 5 | T15: 0 | U15: 0 | V15: 97155.83 | W15: 199184.2 | X15: 179800.05 | Y15: 120222 | Z15: 50.63684 | AA15: 1131.5234 | AB15: 0.096910477 | AC15: 36.117306 | AD15: =D15*'ราคาต้นทุน (Asset)'!$E$1 -> 37866600 | AE15: {=_xlfn.LET(_xlpm.result,INDEX(ASSET!U:U, MATCH(TRIM($C15), TRIM(ASSET!$A:$A), 0)),IF(ISNUMBER(SEARCH("-", _xlpm.result)), 0, _xlpm.result))} -> 3191800 | AF15: =group_data_final[[#This Row],[ค่าบำรุงจุดกางเต็นท์]]/300000 -> 0 | AG15: {=_xlfn.LET(_xlpm.result,INDEX(ราคาค่าบำรุง!D:D, MATCH(TRIM($C15), TRIM(ราคาค่าบำรุง!$A:$A), 0)),IF(ISNUMBER(SEARCH("-", _xlpm.result)), 0, _xlpm.result))} -> 0 | AH15: =group_data_final[[#This Row],[ค่าบำรุงจุดพักรถ]]/300000 -> 1 | AI15: {=_xlfn.LET(_xlpm.result,INDEX(ราคาค่าบำรุง!F:F, MATCH(TRIM($C15), TRIM(ราคาค่าบำรุง!$A:$A), 0)),IF(ISNUMBER(SEARCH("-", _xlpm.result)), 0, _xlpm.result))} -> 300000 | AJ15: =group_data_final[[#This Row],[ค่าบำรุงภูมิสถาปัตย์]]/300000 -> 0 | AK15: {=_xlfn.LET(_xlpm.result,INDEX(ราคาค่าบำรุง!H:H, MATCH(TRIM($C15), TRIM(ราคาค่าบำรุง!$A:$A), 0)),IF(ISNUMBER(SEARCH("-", _xlpm.result)), 0, _xlpm.result))} -> 0 | AL15: =IF(OR(COUNTIF(B15,"*กระบี่*"),COUNTIF(B15,"*จันทบุรี*"),COUNTIF(B15,"*ชุมพร*"),COUNTIF(B15,"*เชียงราย*"),COUNTIF(B15,"*ตรัง*"),COUNTIF(B15,"*นครนายก*"),COUNTIF(B15,"*ปราจีนบุรี*"),COUNTIF(B15,"*พัทลุง*"),COUNTIF(B15,"*ภูเก็ต*"),COUNTIF(B15,"*ยะลา*"),COUNTIF(B15,"*สกลนคร*"),COUNTIF(B15,"*สตูล*"),COUNTIF(B15,"*หนองคาย*"),COUNTIF(B15,"*สุราษฎร์ธานี*"),COUNTIF(B15,"*ปัตตานี*")),2, IF(OR(COUNTIF(B15,"*ตราด*"),COUNTIF(B15,"*นครพนม*"),COUNTIF(B15,"*นครศรีธรรมราช*"),COUNTIF(B15,"*นราธิวาส*"),COUNTIF(B15,"*บึงกาฬ*"),COUNTIF(B15,"*พังงา*"),COUNTIF(B15,"*ระนอง*"),COUNTIF(B15,"*สงขลา*")),4,0)) -> 4 | AM15: =_xlfn.XLOOKUP(group_data_final[[#This Row],[depot_code]],C:C,แผน68!D:D) -> 22852169 | AN15: 9585.5
A16: สำนักงานทางหลวงที่ 16 (นครศรีธรรมราช) | B16: ขท.สุราษฎร์ธานีที่ 2 (กาญจนดิษฐ์) | C16: 328 | D16: {=_xlfn.LET(_xlpm.result,INDEX(ระยะทาง!C:C, MATCH(TRIM(C16), TRIM(ระยะทาง!$A:$A), 0)),IF(ISNUMBER(SEARCH("-", _xlpm.result)), 0, _xlpm.result))} -> 604.326 | E16: {=_xlfn.LET(_xlpm.result,INDEX(ระยะทาง!D:D, MATCH(TRIM($C16), TRIM(ระยะทาง!$A:$A), 0)),IF(ISNUMBER(SEARCH("-", _xlpm.result)), 0, _xlpm.result))} -> 2265182029 | F16: 206441188 | G16: 2.1868571 | H16: 322.261 | I16: 2 | J16: 6 | K16: 3.5714286 | L16: 3.532 | M16: 5 | N16: 0 | T16: 15320 | U16: 0 | V16: 188911.98 | W16: 1665.3 | X16: 309545.47 | Y16: 18438.661 | Z16: 26.385044 | AA16: 98.328851 | AB16: -0.01283958 | AC16: 25.833823 | AD16: =D16*'ราคาต้นทุน (Asset)'!$E$1 -> 36259560 | AE16: {=_xlfn.LET(_xlpm.result,INDEX(ASSET!U:U, MATCH(TRIM($C16), TRIM(ASSET!$A:$A), 0)),IF(ISNUMBER(SEARCH("-", _xlpm.result)), 0, _xlpm.result))} -> 2624800 | AF16: =group_data_final[[#This Row],[ค่าบำรุงจุดกางเต็นท์]]/300000 -> 0 | AG16: {=_xlfn.LET(_xlpm.result,INDEX(ราคาค่าบำรุง!D:D, MATCH(TRIM($C16), TRIM(ราคาค่าบำรุง!$A:$A), 0)),IF(ISNUMBER(SEARCH("-", _xlpm.result)), 0, _xlpm.result))} -> 0 | AH16: =group_data_final[[#This Row],[ค่าบำรุงจุดพักรถ]]/300000 -> 1 | AI16: {=_xlfn.LET(_xlpm.result,INDEX(ราคาค่าบำรุง!F:F, MATCH(TRIM($C16), TRIM(ราคาค่าบำรุง!$A:$A), 0)),IF(ISNUMBER(SEARCH("-", _xlpm.result)), 0, _xlpm.result))} -> 300000 | AJ16: =group_data_final[[#This Row],[ค่าบำรุงภูมิสถาปัตย์]]/300000 -> 1 | AK16: {=_xlfn.LET(_xlpm.result,INDEX(ราคาค่าบำรุง!H:H, MATCH(TRIM($C16), TRIM(ราคาค่าบำรุง!$A:$A), 0)),IF(ISNUMBER(SEARCH("-", _xlpm.result)), 0, _xlpm.result))} -> 300000 | AL16: =IF(OR(COUNTIF(B16,"*กระบี่*"),COUNTIF(B16,"*จันทบุรี*"),COUNTIF(B16,"*ชุมพร*"),COUNTIF(B16,"*เชียงราย*"),COUNTIF(B16,"*ตรัง*"),COUNTIF(B16,"*นครนายก*"),COUNTIF(B16,"*ปราจีนบุรี*"),COUNTIF(B16,"*พัทลุง*"),COUNTIF(B16,"*ภูเก็ต*"),COUNTIF(B16,"*ยะลา*"),COUNTIF(B16,"*สกลนคร*"),COUNTIF(B16,"*สตูล*"),COUNTIF(B16,"*หนองคาย*"),COUNTIF(B16,"*สุราษฎร์ธานี*"),COUNTIF(B16,"*ปัตตานี*")),2, IF(OR(COUNTIF(B16,"*ตราด*"),COUNTIF(B16,"*นครพนม*"),COUNTIF(B16,"*นครศรีธรรมราช*"),COUNTIF(B16,"*นราธิวาส*"),COUNTIF(B16,"*บึงกาฬ*"),COUNTIF(B16,"*พังงา*"),COUNTIF(B16,"*ระนอง*"),COUNTIF(B16,"*สงขลา*")),4,0)) -> 2 | AM16: =_xlfn.XLOOKUP(group_data_final[[#This Row],[depot_code]],C:C,แผน68!D:D) -> 26661756 | AN16: 8649
A17: สำนักงานทางหลวงที่ 16 (นครศรีธรรมราช) | B17: ขท.สุราษฎร์ธานีที่ 3 (เวียงสระ) | C17: 329 | D17: {=_xlfn.LET(_xlpm.result,INDEX(ระยะทาง!C:C, MATCH(TRIM(C17), TRIM(ระยะทาง!$A:$A), 0)),IF(ISNUMBER(SEARCH("-", _xlpm.result)), 0, _xlpm.result))} -> 673.54 | E17: {=_xlfn.LET(_xlpm.result,INDEX(ระยะทาง!D:D, MATCH(TRIM($C17), TRIM(ระยะทาง!$A:$A), 0)),IF(ISNUMBER(SEARCH("-", _xlpm.result)), 0, _xlpm.result))} -> 2893846250 | F17: 352097013 | G17: 2.253 | H17: 304.089 | I17: 2 | J17: 6 | K17: 3.5 | L17: 3.5 | M17: 5 | N17: 4.628 | O17: 2 | P17: 6 | Q17: 4 | T17: 0 | U17: 0 | V17: 80023.69 | W17: 8284 | X17: 71181.69 | Y17: 84163 | Z17: 55.750415 | AA17: 201.86348 | AB17: 0.017444917 | AC17: 31.187232 | AD17: =D17*'ราคาต้นทุน (Asset)'!$E$1 -> 40412400 | AE17: {=_xlfn.LET(_xlpm.result,INDEX(ASSET!U:U, MATCH(TRIM($C17), TRIM(ASSET!$A:$A), 0)),IF(ISNUMBER(SEARCH("-", _xlpm.result)), 0, _xlpm.result))} -> 2533400 | AF17: =group_data_final[[#This Row],[ค่าบำรุงจุดกางเต็นท์]]/300000 -> 0 | AG17: {=_xlfn.LET(_xlpm.result,INDEX(ราคาค่าบำรุง!D:D, MATCH(TRIM($C17), TRIM(ราคาค่าบำรุง!$A:$A), 0)),IF(ISNUMBER(SEARCH("-", _xlpm.result)), 0, _xlpm.result))} -> 0 | AH17: =group_data_final[[#This Row],[ค่าบำรุงจุดพักรถ]]/300000 -> 2 | AI17: {=_xlfn.LET(_xlpm.result,INDEX(ราคาค่าบำรุง!F:F, MATCH(TRIM($C17), TRIM(ราคาค่าบำรุง!$A:$A), 0)),IF(ISNUMBER(SEARCH("-", _xlpm.result)), 0, _xlpm.result))} -> 600000 | AJ17: =group_data_final[[#This Row],[ค่าบำรุงภูมิสถาปัตย์]]/300000 -> 0 | AK17: {=_xlfn.LET(_xlpm.result,INDEX(ราคาค่าบำรุง!H:H, MATCH(TRIM($C17), TRIM(ราคาค่าบำรุง!$A:$A), 0)),IF(ISNUMBER(SEARCH("-", _xlpm.result)), 0, _xlpm.result))} -> 0 | AL17: =IF(OR(COUNTIF(B17,"*กระบี่*"),COUNTIF(B17,"*จันทบุรี*"),COUNTIF(B17,"*ชุมพร*"),COUNTIF(B17,"*เชียงราย*"),COUNTIF(B17,"*ตรัง*"),COUNTIF(B17,"*นครนายก*"),COUNTIF(B17,"*ปราจีนบุรี*"),COUNTIF(B17,"*พัทลุง*"),COUNTIF(B17,"*ภูเก็ต*"),COUNTIF(B17,"*ยะลา*"),COUNTIF(B17,"*สกลนคร*"),COUNTIF(B17,"*สตูล*"),COUNTIF(B17,"*หนองคาย*"),COUNTIF(B17,"*สุราษฎร์ธานี*"),COUNTIF(B17,"*ปัตตานี*")),2, IF(OR(COUNTIF(B17,"*ตราด*"),COUNTIF(B17,"*นครพนม*"),COUNTIF(B17,"*นครศรีธรรมราช*"),COUNTIF(B17,"*นราธิวาส*"),COUNTIF(B17,"*บึงกาฬ*"),COUNTIF(B17,"*พังงา*"),COUNTIF(B17,"*ระนอง*"),COUNTIF(B17,"*สงขลา*")),4,0)) -> 2 | AM17: =_xlfn.XLOOKUP(group_data_final[[#This Row],[depot_code]],C:C,แผน68!D:D) -> 49094616 | AN17: 7855
A18: สำนักงานทางหลวงที่ 17 (กระบี่) | B18: ขท.ระนอง | C18: 331 | D18: {=_xlfn.LET(_xlpm.result,INDEX(ระยะทาง!C:C, MATCH(TRIM(C18), TRIM(ระยะทาง!$A:$A), 0)),IF(ISNUMBER(SEARCH("-", _xlpm.result)), 0, _xlpm.result))} -> 536.827 | E18: {=_xlfn.LET(_xlpm.result,INDEX(ระยะทาง!D:D, MATCH(TRIM($C18), TRIM(ระยะทาง!$A:$A), 0)),IF(ISNUMBER(SEARCH("-", _xlpm.result)), 0, _xlpm.result))} -> 994758501 | F18: 224455317 | G18: 2.74225 | H18: 268.19 | I18: 1 | J18: 6 | K18: 3.5 | L18: 3.5 | M18: 5 | N18: 3.344 | O18: 4 | P18: 4 | Q18: 4 | T18: 21936 | U18: 0 | V18: 42015.05 | W18: 7456.4 | X18: 119997.3 | Y18: 96801 | Z18: 36.928204 | AA18: 1161.6493 | AB18: 0.2009175 | AC18: 51.655285 | AD18: =D18*'ราคาต้นทุน (Asset)'!$E$1 -> 32209620 | AE18: {=_xlfn.LET(_xlpm.result,INDEX(ASSET!U:U, MATCH(TRIM($C18), TRIM(ASSET!$A:$A), 0)),IF(ISNUMBER(SEARCH("-", _xlpm.result)), 0, _xlpm.result))} -> 3081300 | AF18: =group_data_final[[#This Row],[ค่าบำรุงจุดกางเต็นท์]]/300000 -> 0 | AG18: {=_xlfn.LET(_xlpm.result,INDEX(ราคาค่าบำรุง!D:D, MATCH(TRIM($C18), TRIM(ราคาค่าบำรุง!$A:$A), 0)),IF(ISNUMBER(SEARCH("-", _xlpm.result)), 0, _xlpm.result))} -> 0 | AH18: =group_data_final[[#This Row],[ค่าบำรุงจุดพักรถ]]/300000 -> 1 | AI18: {=_xlfn.LET(_xlpm.result,INDEX(ราคาค่าบำรุง!F:F, MATCH(TRIM($C18), TRIM(ราคาค่าบำรุง!$A:$A), 0)),IF(ISNUMBER(SEARCH("-", _xlpm.result)), 0, _xlpm.result))} -> 300000 | AJ18: =group_data_final[[#This Row],[ค่าบำรุงภูมิสถาปัตย์]]/300000 -> 0 | AK18: {=_xlfn.LET(_xlpm.result,INDEX(ราคาค่าบำรุง!H:H, MATCH(TRIM($C18), TRIM(ราคาค่าบำรุง!$A:$A), 0)),IF(ISNUMBER(SEARCH("-", _xlpm.result)), 0, _xlpm.result))} -> 0 | AL18: =IF(OR(COUNTIF(B18,"*กระบี่*"),COUNTIF(B18,"*จันทบุรี*"),COUNTIF(B18,"*ชุมพร*"),COUNTIF(B18,"*เชียงราย*"),COUNTIF(B18,"*ตรัง*"),COUNTIF(B18,"*นครนายก*"),COUNTIF(B18,"*ปราจีนบุรี*"),COUNTIF(B18,"*พัทลุง*"),COUNTIF(B18,"*ภูเก็ต*"),COUNTIF(B18,"*ยะลา*"),COUNTIF(B18,"*สกลนคร*"),COUNTIF(B18,"*สตูล*"),COUNTIF(B18,"*หนองคาย*"),COUNTIF(B18,"*สุราษฎร์ธานี*"),COUNTIF(B18,"*ปัตตานี*")),2, IF(OR(COUNTIF(B18,"*ตราด*"),COUNTIF(B18,"*นครพนม*"),COUNTIF(B18,"*นครศรีธรรมราช*"),COUNTIF(B18,"*นราธิวาส*"),COUNTIF(B18,"*บึงกาฬ*"),COUNTIF(B18,"*พังงา*"),COUNTIF(B18,"*ระนอง*"),COUNTIF(B18,"*สงขลา*")),4,0)) -> 4 | AM18: =_xlfn.XLOOKUP(group_data_final[[#This Row],[depot_code]],C:C,แผน68!D:D) -> 35764703 | AN18: 7390
A19: สำนักงานทางหลวงที่ 15 (ประจวบคีรีขันธ์) | B19: ขท.ชุมพร | C19: 332 | D19: {=_xlfn.LET(_xlpm.result,INDEX(ระยะทาง!C:C, MATCH(TRIM(C19), TRIM(ระยะทาง!$A:$A), 0)),IF(ISNUMBER(SEARCH("-", _xlpm.result)), 0, _xlpm.result))} -> 661.423 | E19: {=_xlfn.LET(_xlpm.result,INDEX(ระยะทาง!D:D, MATCH(TRIM($C19), TRIM(ระยะทาง!$A:$A), 0)),IF(ISNUMBER(SEARCH("-", _xlpm.result)), 0, _xlpm.result))} -> 2142184953 | F19: 758169463 | G19: 2.3232857 | H19: 310.773 | I19: 2 | J19: 6 | K19: 3.1428571 | L19: 3.5 | M19: 6 | N19: 69.258 | O19: 2 | P19: 4 | Q19: 3.4285714 | R19: 3.5 | S19: 5.1666667 | T19: 0 | U19: 0 | V19: 283505.86 | W19: 2204.8 | X19: 165962.01 | Y19: 227064 | Z19: 21.335998 | AA19: 172.81534 | AB19: -0.08587616 | AC19: 17.832183 | AD19: =D19*'ราคาต้นทุน (Asset)'!$E$1 -> 39685380 | AE19: {=_xlfn.LET(_xlpm.result,INDEX(ASSET!U:U, MATCH(TRIM($C19), TRIM(ASSET!$A:$A), 0)),IF(ISNUMBER(SEARCH("-", _xlpm.result)), 0, _xlpm.result))} -> 3167100 | AF19: =group_data_final[[#This Row],[ค่าบำรุงจุดกางเต็นท์]]/300000 -> 1 | AG19: {=_xlfn.LET(_xlpm.result,INDEX(ราคาค่าบำรุง!D:D, MATCH(TRIM($C19), TRIM(ราคาค่าบำรุง!$A:$A), 0)),IF(ISNUMBER(SEARCH("-", _xlpm.result)), 0, _xlpm.result))} -> 300000 | AH19: =group_data_final[[#This Row],[ค่าบำรุงจุดพักรถ]]/300000 -> 0 | AI19: {=_xlfn.LET(_xlpm.result,INDEX(ราคาค่าบำรุง!F:F, MATCH(TRIM($C19), TRIM(ราคาค่าบำรุง!$A:$A), 0)),IF(ISNUMBER(SEARCH("-", _xlpm.result)), 0, _xlpm.result))} -> 0 | AJ19: =group_data_final[[#This Row],[ค่าบำรุงภูมิสถาปัตย์]]/300000 -> 0 | AK19: {=_xlfn.LET(_xlpm.result,INDEX(ราคาค่าบำรุง!H:H, MATCH(TRIM($C19), TRIM(ราคาค่าบำรุง!$A:$A), 0)),IF(ISNUMBER(SEARCH("-", _xlpm.result)), 0, _xlpm.result))} -> 0 | AL19: =IF(OR(COUNTIF(B19,"*กระบี่*"),COUNTIF(B19,"*จันทบุรี*"),COUNTIF(B19,"*ชุมพร*"),COUNTIF(B19,"*เชียงราย*"),COUNTIF(B19,"*ตรัง*"),COUNTIF(B19,"*นครนายก*"),COUNTIF(B19,"*ปราจีนบุรี*"),COUNTIF(B19,"*พัทลุง*"),COUNTIF(B19,"*ภูเก็ต*"),COUNTIF(B19,"*ยะลา*"),COUNTIF(B19,"*สกลนคร*"),COUNTIF(B19,"*สตูล*"),COUNTIF(B19,"*หนองคาย*"),COUNTIF(B19,"*สุราษฎร์ธานี*"),COUNTIF(B19,"*ปัตตานี*")),2, IF(OR(COUNTIF(B19,"*ตราด*"),COUNTIF(B19,"*นครพนม*"),COUNTIF(B19,"*นครศรีธรรมราช*"),COUNTIF(B19,"*นราธิวาส*"),COUNTIF(B19,"*บึงกาฬ*"),COUNTIF(B19,"*พังงา*"),COUNTIF(B19,"*ระนอง*"),COUNTIF(B19,"*สงขลา*")),4,0)) -> 2 | AM19: =_xlfn.XLOOKUP(group_data_final[[#This Row],[depot_code]],C:C,แผน68!D:D) -> 17220342 | AN19: 8576
A20: สำนักงานทางหลวงที่ 15 (ประจวบคีรีขันธ์) | B20: ขท.ประจวบคีรีขันธ์ (หัวหิน) | C20: 333 | D20: {=_xlfn.LET(_xlpm.result,INDEX(ระยะทาง!C:C, MATCH(TRIM(C20), TRIM(ระยะทาง!$A:$A), 0)),IF(ISNUMBER(SEARCH("-", _xlpm.result)), 0, _xlpm.result))} -> 721.525 | E20: {=_xlfn.LET(_xlpm.result,INDEX(ระยะทาง!D:D, MATCH(TRIM($C20), TRIM(ระยะทาง!$A:$A), 0)),IF(ISNUMBER(SEARCH("-", _xlpm.result)), 0, _xlpm.result))} -> 1298448961 | F20: 509205403 | G20: 2.0094286 | H20: 485.206 | I20: 2 | J20: 10 | K20: 4 | L20: 3.5 | M20: 5 | N20: 11.374 | O20: 4 | P20: 8 | Q20: 5 | R20: 3.5 | S20: 4.7333333 | T20: 36547.73 | U20: 19560.68 | V20: 188116.78 | W20: 4175.25 | X20: 240902.6 | Y20: 195405 | Z20: 27.810755 | AA20: 165.39513 | AB20: -0.046238055 | AC20: 10.670958 | AD20: =D20*'ราคาต้นทุน (Asset)'!$E$1 -> 43291500 | AE20: {=_xlfn.LET(_xlpm.result,INDEX(ASSET!U:U, MATCH(TRIM($C20), TRIM(ASSET!$A:$A), 0)),IF(ISNUMBER(SEARCH("-", _xlpm.result)), 0, _xlpm.result))} -> 3325700 | AF20: =group_data_final[[#This Row],[ค่าบำรุงจุดกางเต็นท์]]/300000 -> 1 | AG20: {=_xlfn.LET(_xlpm.result,INDEX(ราคาค่าบำรุง!D:D, MATCH(TRIM($C20), TRIM(ราคาค่าบำรุง!$A:$A), 0)),IF(ISNUMBER(SEARCH("-", _xlpm.result)), 0, _xlpm.result))} -> 300000 | AH20: =group_data_final[[#This Row],[ค่าบำรุงจุดพักรถ]]/300000 -> 2 | AI20: {=_xlfn.LET(_xlpm.result,INDEX(ราคาค่าบำรุง!F:F, MATCH(TRIM($C20), TRIM(ราคาค่าบำรุง!$A:$A), 0)),IF(ISNUMBER(SEARCH("-", _xlpm.result)), 0, _xlpm.result))} -> 600000 | AJ20: =group_data_final[[#This Row],[ค่าบำรุงภูมิสถาปัตย์]]/300000 -> 0 | AK20: {=_xlfn.LET(_xlpm.result,INDEX(ราคาค่าบำรุง!H:H, MATCH(TRIM($C20), TRIM(ราคาค่าบำรุง!$A:$A), 0)),IF(ISNUMBER(SEARCH("-", _xlpm.result)), 0, _xlpm.result))} -> 0 | AL20: =IF(OR(COUNTIF(B20,"*กระบี่*"),COUNTIF(B20,"*จันทบุรี*"),COUNTIF(B20,"*ชุมพร*"),COUNTIF(B20,"*เชียงราย*"),COUNTIF(B20,"*ตรัง*"),COUNTIF(B20,"*นครนายก*"),COUNTIF(B20,"*ปราจีนบุรี*"),COUNTIF(B20,"*พัทลุง*"),COUNTIF(B20,"*ภูเก็ต*"),COUNTIF(B20,"*ยะลา*"),COUNTIF(B20,"*สกลนคร*"),COUNTIF(B20,"*สตูล*"),COUNTIF(B20,"*หนองคาย*"),COUNTIF(B20,"*สุราษฎร์ธานี*"),COUNTIF(B20,"*ปัตตานี*")),2, IF(OR(COUNTIF(B20,"*ตราด*"),COUNTIF(B20,"*นครพนม*"),COUNTIF(B20,"*นครศรีธรรมราช*"),COUNTIF(B20,"*นราธิวาส*"),COUNTIF(B20,"*บึงกาฬ*"),COUNTIF(B20,"*พังงา*"),COUNTIF(B20,"*ระนอง*"),COUNTIF(B20,"*สงขลา*")),4,0)) -> 0 | AM20: =_xlfn.XLOOKUP(group_data_final[[#This Row],[depot_code]],C:C,แผน68!D:D) -> 43935647 | AN20: 6936.2
A21: สำนักงานทางหลวงที่ 15 (ประจวบคีรีขันธ์) | B21: ขท.ราชบุรี | C21: 335 | D21: {=_xlfn.LET(_xlpm.result,INDEX(ระยะทาง!C:C, MATCH(TRIM(C21), TRIM(ระยะทาง!$A:$A), 0)),IF(ISNUMBER(SEARCH("-", _xlpm.result)), 0, _xlpm.result))} -> 631.802 | E21: {=_xlfn.LET(_xlpm.result,INDEX(ระยะทาง!D:D, MATCH(TRIM($C21), TRIM(ระยะทาง!$A:$A), 0)),IF(ISNUMBER(SEARCH("-", _xlpm.result)), 0, _xlpm.result))} -> 2763952440 | F21: 460587578 | G21: 2.209 | H21: 136.813 | I21: 2 | J21: 8 | K21: 3.6 | L21: 3.536 | M21: 5 | N21: 29.245 | O21: 2 | P21: 6 | Q21: 4.75 | R21: 3.4375 | S21: 5 | T21: 0 | U21: 0 | V21: 90565 | W21: 6216.25 | X21: 1167.628 | Y21: 32936 | Z21: 26.385855 | AA21: 149.36671 | AB21: 0.044123985 | AC21: 10.703423 | AD21: =D21*'ราคาต้นทุน (Asset)'!$E$1 -> 37908120 | AE21: {=_xlfn.LET(_xlpm.result,INDEX(ASSET!U:U, MATCH(TRIM($C21), TRIM(ASSET!$A:$A), 0)),IF(ISNUMBER(SEARCH("-", _xlpm.result)), 0, _xlpm.result))} -> 5526100 | AF21: =group_data_final[[#This Row],[ค่าบำรุงจุดกางเต็นท์]]/300000 -> 0 | AG21: {=_xlfn.LET(_xlpm.result,INDEX(ราคาค่าบำรุง!D:D, MATCH(TRIM($C21), TRIM(ราคาค่าบำรุง!$A:$A), 0)),IF(ISNUMBER(SEARCH("-", _xlpm.result)), 0, _xlpm.result))} -> 0 | AH21: =group_data_final[[#This Row],[ค่าบำรุงจุดพักรถ]]/300000 -> 2 | AI21: {=_xlfn.LET(_xlpm.result,INDEX(ราคาค่าบำรุง!F:F, MATCH(TRIM($C21), TRIM(ราคาค่าบำรุง!$A:$A), 0)),IF(ISNUMBER(SEARCH("-", _xlpm.result)), 0, _xlpm.result))} -> 600000 | AJ21: =group_data_final[[#This Row],[ค่าบำรุงภูมิสถาปัตย์]]/300000 -> 1 | AK21: {=_xlfn.LET(_xlpm.result,INDEX(ราคาค่าบำรุง!H:H, MATCH(TRIM($C21), TRIM(ราคาค่าบำรุง!$A:$A), 0)),IF(ISNUMBER(SEARCH("-", _xlpm.result)), 0, _xlpm.result))} -> 300000 | AL21: =IF(OR(COUNTIF(B21,"*กระบี่*"),COUNTIF(B21,"*จันทบุรี*"),COUNTIF(B21,"*ชุมพร*"),COUNTIF(B21,"*เชียงราย*"),COUNTIF(B21,"*ตรัง*"),COUNTIF(B21,"*นครนายก*"),COUNTIF(B21,"*ปราจีนบุรี*"),COUNTIF(B21,"*พัทลุง*"),COUNTIF(B21,"*ภูเก็ต*"),COUNTIF(B21,"*ยะลา*"),COUNTIF(B21,"*สกลนคร*"),COUNTIF(B21,"*สตูล*"),COUNTIF(B21,"*หนองคาย*"),COUNTIF(B21,"*สุราษฎร์ธานี*"),COUNTIF(B21,"*ปัตตานี*")),2, IF(OR(COUNTIF(B21,"*ตราด*"),COUNTIF(B21,"*นครพนม*"),COUNTIF(B21,"*นครศรีธรรมราช*"),COUNTIF(B21,"*นราธิวาส*"),COUNTIF(B21,"*บึงกาฬ*"),COUNTIF(B21,"*พังงา*"),COUNTIF(B21,"*ระนอง*"),COUNTIF(B21,"*สงขลา*")),4,0)) -> 0 | AM21: =_xlfn.XLOOKUP(group_data_final[[#This Row],[depot_code]],C:C,แผน68!D:D) -> 2925773 | AN21: 9850
A22: สำนักงานทางหลวงที่ 15 (ประจวบคีรีขันธ์) | B22: ขท.นครปฐม | C22: 336 | D22: {=_xlfn.LET(_xlpm.result,INDEX(ระยะทาง!C:C, MATCH(TRIM(C22), TRIM(ระยะทาง!$A:$A), 0)),IF(ISNUMBER(SEARCH("-", _xlpm.result)), 0, _xlpm.result))} -> 600.327 | E22: {=_xlfn.LET(_xlpm.result,INDEX(ระยะทาง!D:D, MATCH(TRIM($C22), TRIM(ระยะทาง!$A:$A), 0)),IF(ISNUMBER(SEARCH("-", _xlpm.result)), 0, _xlpm.result))} -> 2439163877 | F22: 213101050 | G22: 3.443875 | H22: 167.708 | I22: 4 | J22: 8 | K22: 4.8 | L22: 3.5 | M22: 5 | N22: 209.74 | O22: 1 | P22: 10 | Q22: 5.375 | R22: 3.46875 | S22: 4.304 | T22: 0 | U22: 0 | V22: 265054.06 | W22: 3940 | X22: 93482.07 | Y22: 9719.188 | Z22: 6.5962978 | AA22: 2.1713018 | AB22: -0.012259916 | AC22: 4.7394353 | AD22: =D22*'ราคาต้นทุน (Asset)'!$E$1 -> 36019620 | AE22: {=_xlfn.LET(_xlpm.result,INDEX(ASSET!U:U, MATCH(TRIM($C22), TRIM(ASSET!$A:$A), 0)),IF(ISNUMBER(SEARCH("-", _xlpm.result)), 0, _xlpm.result))} -> 3809500 | AF22: =group_data_final[[#This Row],[ค่าบำรุงจุดกางเต็นท์]]/300000 -> 0 | AG22: {=_xlfn.LET(_xlpm.result,INDEX(ราคาค่าบำรุง!D:D, MATCH(TRIM($C22), TRIM(ราคาค่าบำรุง!$A:$A), 0)),IF(ISNUMBER(SEARCH("-", _xlpm.result)), 0, _xlpm.result))} -> 0 | AH22: =group_data_final[[#This Row],[ค่าบำรุงจุดพักรถ]]/300000 -> 3 | AI22: {=_xlfn.LET(_xlpm.result,INDEX(ราคาค่าบำรุง!F:F, MATCH(TRIM($C22), TRIM(ราคาค่าบำรุง!$A:$A), 0)),IF(ISNUMBER(SEARCH("-", _xlpm.result)), 0, _xlpm.result))} -> 900000 | AJ22: =group_data_final[[#This Row],[ค่าบำรุงภูมิสถาปัตย์]]/300000 -> 0 | AK22: {=_xlfn.LET(_xlpm.result,INDEX(ราคาค่าบำรุง!H:H, MATCH(TRIM($C22), TRIM(ราคาค่าบำรุง!$A:$A), 0)),IF(ISNUMBER(SEARCH("-", _xlpm.result)), 0, _xlpm.result))} -> 0 | AL22: =IF(OR(COUNTIF(B22,"*กระบี่*"),COUNTIF(B22,"*จันทบุรี*"),COUNTIF(B22,"*ชุมพร*"),COUNTIF(B22,"*เชียงราย*"),COUNTIF(B22,"*ตรัง*"),COUNTIF(B22,"*นครนายก*"),COUNTIF(B22,"*ปราจีนบุรี*"),COUNTIF(B22,"*พัทลุง*"),COUNTIF(B22,"*ภูเก็ต*"),COUNTIF(B22,"*ยะลา*"),COUNTIF(B22,"*สกลนคร*"),COUNTIF(B22,"*สตูล*"),COUNTIF(B22,"*หนองคาย*"),COUNTIF(B22,"*สุราษฎร์ธานี*"),COUNTIF(B22,"*ปัตตานี*")),2, IF(OR(COUNTIF(B22,"*ตราด*"),COUNTIF(B22,"*นครพนม*"),COUNTIF(B22,"*นครศรีธรรมราช*"),COUNTIF(B22,"*นราธิวาส*"),COUNTIF(B22,"*บึงกาฬ*"),COUNTIF(B22,"*พังงา*"),COUNTIF(B22,"*ระนอง*"),COUNTIF(B22,"*สงขลา*")),4,0)) -> 0 | AM22: =_xlfn.XLOOKUP(group_data_final[[#This Row],[depot_code]],C:C,แผน68!D:D) -> 14895310 | AN22: 9966.1
A23: สำนักงานทางหลวงที่ 15 (ประจวบคีรีขันธ์) | B23: ขท.สมุทรสงคราม | C23: 337 | D23: {=_xlfn.LET(_xlpm.result,INDEX(ระยะทาง!C:C, MATCH(TRIM(C23), TRIM(ระยะทาง!$A:$A), 0)),IF(ISNUMBER(SEARCH("-", _xlpm.result)), 0, _xlpm.result))} -> 527.11 | E23: {=_xlfn.LET(_xlpm.result,INDEX(ระยะทาง!D:D, MATCH(TRIM($C23), TRIM(ระยะทาง!$A:$A), 0)),IF(ISNUMBER(SEARCH("-", _xlpm.result)), 0, _xlpm.result))} -> 2463770612 | F23: 327730651 | G23: 2.0636667 | H23: 216.4 | I23: 1 | J23: 6 | K23: 3.6666667 | L23: 3.5 | M23: 5 | N23: 3.089 | O23: 2 | P23: 6 | Q23: 4 | R23: 3.3333333 | S23: 3.5 | T23: 0 | U23: 0 | V23: 25598.18 | W23: 3061 | X23: 82989.68 | Y23: 1202 | Z23: 18.751491 | AA23: 405.35033 | AB23: -0.070955345 | AC23: 9.3241965 | AD23: =D23*'ราคาต้นทุน (Asset)'!$E$1 -> 31626600 | AE23: {=_xlfn.LET(_xlpm.result,INDEX(ASSET!U:U, MATCH(TRIM($C23), TRIM(ASSET!$A:$A), 0)),IF(ISNUMBER(SEARCH("-", _xlpm.result)), 0, _xlpm.result))} -> 2678700 | AF23: =group_data_final[[#This Row],[ค่าบำรุงจุดกางเต็นท์]]/300000 -> 0 | AG23: {=_xlfn.LET(_xlpm.result,INDEX(ราคาค่าบำรุง!D:D, MATCH(TRIM($C23), TRIM(ราคาค่าบำรุง!$A:$A), 0)),IF(ISNUMBER(SEARCH("-", _xlpm.result)), 0, _xlpm.result))} -> 0 | AH23: =group_data_final[[#This Row],[ค่าบำรุงจุดพักรถ]]/300000 -> 1 | AI23: {=_xlfn.LET(_xlpm.result,INDEX(ราคาค่าบำรุง!F:F, MATCH(TRIM($C23), TRIM(ราคาค่าบำรุง!$A:$A), 0)),IF(ISNUMBER(SEARCH("-", _xlpm.result)), 0, _xlpm.result))} -> 300000 | AJ23: =group_data_final[[#This Row],[ค่าบำรุงภูมิสถาปัตย์]]/300000 -> 0 | AK23: {=_xlfn.LET(_xlpm.result,INDEX(ราคาค่าบำรุง!H:H, MATCH(TRIM($C23), TRIM(ราคาค่าบำรุง!$A:$A), 0)),IF(ISNUMBER(SEARCH("-", _xlpm.result)), 0, _xlpm.result))} -> 0 | AL23: =IF(OR(COUNTIF(B23,"*กระบี่*"),COUNTIF(B23,"*จันทบุรี*"),COUNTIF(B23,"*ชุมพร*"),COUNTIF(B23,"*เชียงราย*"),COUNTIF(B23,"*ตรัง*"),COUNTIF(B23,"*นครนายก*"),COUNTIF(B23,"*ปราจีนบุรี*"),COUNTIF(B23,"*พัทลุง*"),COUNTIF(B23,"*ภูเก็ต*"),COUNTIF(B23,"*ยะลา*"),COUNTIF(B23,"*สกลนคร*"),COUNTIF(B23,"*สตูล*"),COUNTIF(B23,"*หนองคาย*"),COUNTIF(B23,"*สุราษฎร์ธานี*"),COUNTIF(B23,"*ปัตตานี*")),2, IF(OR(COUNTIF(B23,"*ตราด*"),COUNTIF(B23,"*นครพนม*"),COUNTIF(B23,"*นครศรีธรรมราช*"),COUNTIF(B23,"*นราธิวาส*"),COUNTIF(B23,"*บึงกาฬ*"),COUNTIF(B23,"*พังงา*"),COUNTIF(B23,"*ระนอง*"),COUNTIF(B23,"*สงขลา*")),4,0)) -> 0 | AM23: =_xlfn.XLOOKUP(group_data_final[[#This Row],[depot_code]],C:C,แผน68!D:D) -> 18362201 | AN23: 11938.45
A24: สำนักงานทางหลวงที่ 15 (ประจวบคีรีขันธ์) | B24: ขท.เพชรบุรี | C24: 338 | D24: {=_xlfn.LET(_xlpm.result,INDEX(ระยะทาง!C:C, MATCH(TRIM(C24), TRIM(ระยะทาง!$A:$A), 0)),IF(ISNUMBER(SEARCH("-", _xlpm.result)), 0, _xlpm.result))} -> 711.869 | E24: {=_xlfn.LET(_xlpm.result,INDEX(ระยะทาง!D:D, MATCH(TRIM($C24), TRIM(ระยะทาง!$A:$A), 0)),IF(ISNUMBER(SEARCH("-", _xlpm.result)), 0, _xlpm.result))} -> 1434933767 | F24: 373691851 | G24: 2.1635 | H24: 395.896 | I24: 2 | J24: 6 | K24: 3 | L24: 5.5 | M24: 5 | N24: 12.129 | O24: 2 | P24: 6 | Q24: 3.75 | R24: 4.5595 | S24: 4.889 | T24: 0 | U24: 0 | V24: 22623.65 | W24: 18739.1 | X24: 40715.391 | Y24: 31114 | Z24: 60.201237 | AA24: 337.69282 | AB24: -0.050340711 | AC24: 10.221809 | AD24: =D24*'ราคาต้นทุน (Asset)'!$E$1 -> 42712140 | AE24: {=_xlfn.LET(_xlpm.result,INDEX(ASSET!U:U, MATCH(TRIM($C24), TRIM(ASSET!$A:$A), 0)),IF(ISNUMBER(SEARCH("-", _xlpm.result)), 0, _xlpm.result))} -> 3795800 | AF24: =group_data_final[[#This Row],[ค่าบำรุงจุดกางเต็นท์]]/300000 -> 0 | AG24: {=_xlfn.LET(_xlpm.result,INDEX(ราคาค่าบำรุง!D:D, MATCH(TRIM($C24), TRIM(ราคาค่าบำรุง!$A:$A), 0)),IF(ISNUMBER(SEARCH("-", _xlpm.result)), 0, _xlpm.result))} -> 0 | AH24: =group_data_final[[#This Row],[ค่าบำรุงจุดพักรถ]]/300000 -> 1 | AI24: {=_xlfn.LET(_xlpm.result,INDEX(ราคาค่าบำรุง!F:F, MATCH(TRIM($C24), TRIM(ราคาค่าบำรุง!$A:$A), 0)),IF(ISNUMBER(SEARCH("-", _xlpm.result)), 0, _xlpm.result))} -> 300000 | AJ24: =group_data_final[[#This Row],[ค่าบำรุงภูมิสถาปัตย์]]/300000 -> 0 | AK24: {=_xlfn.LET(_xlpm.result,INDEX(ราคาค่าบำรุง!H:H, MATCH(TRIM($C24), TRIM(ราคาค่าบำรุง!$A:$A), 0)),IF(ISNUMBER(SEARCH("-", _xlpm.result)), 0, _xlpm.result))} -> 0 | AL24: =IF(OR(COUNTIF(B24,"*กระบี่*"),COUNTIF(B24,"*จันทบุรี*"),COUNTIF(B24,"*ชุมพร*"),COUNTIF(B24,"*เชียงราย*"),COUNTIF(B24,"*ตรัง*"),COUNTIF(B24,"*นครนายก*"),COUNTIF(B24,"*ปราจีนบุรี*"),COUNTIF(B24,"*พัทลุง*"),COUNTIF(B24,"*ภูเก็ต*"),COUNTIF(B24,"*ยะลา*"),COUNTIF(B24,"*สกลนคร*"),COUNTIF(B24,"*สตูล*"),COUNTIF(B24,"*หนองคาย*"),COUNTIF(B24,"*สุราษฎร์ธานี*"),COUNTIF(B24,"*ปัตตานี*")),2, IF(OR(COUNTIF(B24,"*ตราด*"),COUNTIF(B24,"*นครพนม*"),COUNTIF(B24,"*นครศรีธรรมราช*"),COUNTIF(B24,"*นราธิวาส*"),COUNTIF(B24,"*บึงกาฬ*"),COUNTIF(B24,"*พังงา*"),COUNTIF(B24,"*ระนอง*"),COUNTIF(B24,"*สงขลา*")),4,0)) -> 0 | AM24: =_xlfn.XLOOKUP(group_data_final[[#This Row],[depot_code]],C:C,แผน68!D:D) -> 23268968 | AN24: 9546.911
A25: สำนักงานทางหลวงที่ 13 (กรุงเทพ) | B25: ขท.กรุงเทพ | C25: 411 | D25: {=_xlfn.LET(_xlpm.result,INDEX(ระยะทาง!C:C, MATCH(TRIM(C25), TRIM(ระยะทาง!$A:$A), 0)),IF(ISNUMBER(SEARCH("-", _xlpm.result)), 0, _xlpm.result))} -> 566.444 | E25: {=_xlfn.LET(_xlpm.result,INDEX(ระยะทาง!D:D, MATCH(TRIM($C25), TRIM(ระยะทาง!$A:$A), 0)),IF(ISNUMBER(SEARCH("-", _xlpm.result)), 0, _xlpm.result))} -> 7519309714 | F25: 452053776 | G25: 3.4143846 | H25: 140.483 | I25: 1 | J25: 12 | K25: 7.125 | L25: 3.5 | M25: 7.4 | N25: 272.999 | O25: 2 | P25: 18 | Q25: 7 | R25: 3.4655 | S25: 5.69825 | T25: 13750 | U25: 0 | V25: 310071.32 | W25: 106000.9 | X25: 74971.627 | Y25: 47034.899 | Z25: 65.16011 | AA25: 1402.7974 | AB25: 0.092167562 | AC25: 26.720262 | AD25: =D25*'ราคาต้นทุน (Asset)'!$E$1 -> 33986640 | AE25: {=_xlfn.LET(_xlpm.result,INDEX(ASSET!U:U, MATCH(TRIM($C25), TRIM(ASSET!$A:$A), 0)),IF(ISNUMBER(SEARCH("-", _xlpm.result)), 0, _xlpm.result))} -> 5661600 | AF25: =group_data_final[[#This Row],[ค่าบำรุงจุดกางเต็นท์]]/300000 -> 0 | AG25: {=_xlfn.LET(_xlpm.result,INDEX(ราคาค่าบำรุง!D:D, MATCH(TRIM($C25), TRIM(ราคาค่าบำรุง!$A:$A), 0)),IF(ISNUMBER(SEARCH("-", _xlpm.result)), 0, _xlpm.result))} -> 0 | AH25: =group_data_final[[#This Row],[ค่าบำรุงจุดพักรถ]]/300000 -> 0 | AI25: {=_xlfn.LET(_xlpm.result,INDEX(ราคาค่าบำรุง!F:F, MATCH(TRIM($C25), TRIM(ราคาค่าบำรุง!$A:$A), 0)),IF(ISNUMBER(SEARCH("-", _xlpm.result)), 0, _xlpm.result))} -> 0 | AJ25: =group_data_final[[#This Row],[ค่าบำรุงภูมิสถาปัตย์]]/300000 -> 0 | AK25: {=_xlfn.LET(_xlpm.result,INDEX(ราคาค่าบำรุง!H:H, MATCH(TRIM($C25), TRIM(ราคาค่าบำรุง!$A:$A), 0)),IF(ISNUMBER(SEARCH("-", _xlpm.result)), 0, _xlpm.result))} -> 0 | AL25: =IF(OR(COUNTIF(B25,"*กระบี่*"),COUNTIF(B25,"*จันทบุรี*"),COUNTIF(B25,"*ชุมพร*"),COUNTIF(B25,"*เชียงราย*"),COUNTIF(B25,"*ตรัง*"),COUNTIF(B25,"*นครนายก*"),COUNTIF(B25,"*ปราจีนบุรี*"),COUNTIF(B25,"*พัทลุง*"),COUNTIF(B25,"*ภูเก็ต*"),COUNTIF(B25,"*ยะลา*"),COUNTIF(B25,"*สกลนคร*"),COUNTIF(B25,"*สตูล*"),COUNTIF(B25,"*หนองคาย*"),COUNTIF(B25,"*สุราษฎร์ธานี*"),COUNTIF(B25,"*ปัตตานี*")),2, IF(OR(COUNTIF(B25,"*ตราด*"),COUNTIF(B25,"*นครพนม*"),COUNTIF(B25,"*นครศรีธรรมราช*"),COUNTIF(B25,"*นราธิวาส*"),COUNTIF(B25,"*บึงกาฬ*"),COUNTIF(B25,"*พังงา*"),COUNTIF(B25,"*ระนอง*"),COUNTIF(B25,"*สงขลา*")),4,0)) -> 0 | AM25: =_xlfn.XLOOKUP(group_data_final[[#This Row],[depot_code]],C:C,แผน68!D:D) -> 28246563 | AN25: 33899.956
A26: สำนักงานทางหลวงที่ 13 (กรุงเทพ) | B26: ขท.อยุธยา | C26: 413 | D26: {=_xlfn.LET(_xlpm.result,INDEX(ระยะทาง!C:C, MATCH(TRIM(C26), TRIM(ระยะทาง!$A:$A), 0)),IF(ISNUMBER(SEARCH("-", _xlpm.result)), 0, _xlpm.result))} -> 915.242 | E26: {=_xlfn.LET(_xlpm.result,INDEX(ระยะทาง!D:D, MATCH(TRIM($C26), TRIM(ระยะทาง!$A:$A), 0)),IF(ISNUMBER(SEARCH("-", _xlpm.result)), 0, _xlpm.result))} -> 1318106863 | F26: 236324562 | G26: 2.8519474 | H26: 338.72 | I26: 2 | J26: 10 | K26: 4.2666667 | L26: 3.583 | M26: 5 | N26: 355.73 | O26: 1 | P26: 10 | Q26: 3.75 | R26: 3.8746667 | S26: 3.9500909 | T26: 0 | U26: 0 | V26: 13275 | W26: 0 | X26: 25771.168 | Y26: 23.497 | Z26: 6.5656053 | AA26: 1.3719488 | AB26: 0.010495491 | AC26: 6.2973561 | AD26: =D26*'ราคาต้นทุน (Asset)'!$E$1 -> 54914520 | AE26: {=_xlfn.LET(_xlpm.result,INDEX(ASSET!U:U, MATCH(TRIM($C26), TRIM(ASSET!$A:$A), 0)),IF(ISNUMBER(SEARCH("-", _xlpm.result)), 0, _xlpm.result))} -> 3663400 | AF26: =group_data_final[[#This Row],[ค่าบำรุงจุดกางเต็นท์]]/300000 -> 1 | AG26: {=_xlfn.LET(_xlpm.result,INDEX(ราคาค่าบำรุง!D:D, MATCH(TRIM($C26), TRIM(ราคาค่าบำรุง!$A:$A), 0)),IF(ISNUMBER(SEARCH("-", _xlpm.result)), 0, _xlpm.result))} -> 300000 | AH26: =group_data_final[[#This Row],[ค่าบำรุงจุดพักรถ]]/300000 -> 0 | AI26: {=_xlfn.LET(_xlpm.result,INDEX(ราคาค่าบำรุง!F:F, MATCH(TRIM($C26), TRIM(ราคาค่าบำรุง!$A:$A), 0)),IF(ISNUMBER(SEARCH("-", _xlpm.result)), 0, _xlpm.result))} -> 0 | AJ26: =group_data_final[[#This Row],[ค่าบำรุงภูมิสถาปัตย์]]/300000 -> 0 | AK26: {=_xlfn.LET(_xlpm.result,INDEX(ราคาค่าบำรุง!H:H, MATCH(TRIM($C26), TRIM(ราคาค่าบำรุง!$A:$A), 0)),IF(ISNUMBER(SEARCH("-", _xlpm.result)), 0, _xlpm.result))} -> 0 | AL26: =IF(OR(COUNTIF(B26,"*กระบี่*"),COUNTIF(B26,"*จันทบุรี*"),COUNTIF(B26,"*ชุมพร*"),COUNTIF(B26,"*เชียงราย*"),COUNTIF(B26,"*ตรัง*"),COUNTIF(B26,"*นครนายก*"),COUNTIF(B26,"*ปราจีนบุรี*"),COUNTIF(B26,"*พัทลุง*"),COUNTIF(B26,"*ภูเก็ต*"),COUNTIF(B26,"*ยะลา*"),COUNTIF(B26,"*สกลนคร*"),COUNTIF(B26,"*สตูล*"),COUNTIF(B26,"*หนองคาย*"),COUNTIF(B26,"*สุราษฎร์ธานี*"),COUNTIF(B26,"*ปัตตานี*")),2, IF(OR(COUNTIF(B26,"*ตราด*"),COUNTIF(B26,"*นครพนม*"),COUNTIF(B26,"*นครศรีธรรมราช*"),COUNTIF(B26,"*นราธิวาส*"),COUNTIF(B26,"*บึงกาฬ*"),COUNTIF(B26,"*พังงา*"),COUNTIF(B26,"*ระนอง*"),COUNTIF(B26,"*สงขลา*")),4,0)) -> 0 | AM26: =_xlfn.XLOOKUP(group_data_final[[#This Row],[depot_code]],C:C,แผน68!D:D) -> 17901066 | AN26: 28840.904
